Workbook

Sheet Data
A1: BK No | B1: VSL | C1: VOY | D1: ETD | E1: POR | F1: LOD | G1: DIS | H1: TPSZ | I1: Pickup | J1: Pickup Name | K1: TRAN DT | L1: DOC CUST | M1: ORG CUST | N1: COMMODITY | O1: TRAFFIC ORDER | P1: COMMON REMARK | Q1: GP22 | R1: GP42 | S1: GP45 | T1: RE22 | U1: RE45 | V1: UT22 | W1: UT42 | X1: PC22 | Y1: PC42 | Z1: Pickup | AA1: Return | AB1: Balance (Booked - Pickup) | AC1: Group | AD1: GP22 Remaining | AE1: GP42 Remaining | AF1: GP45 Remaining | AG1: RE22 Remaining | AH1: RE45 Remaining | AI1: UT22 Remaining | AJ1: UT42 Remaining | AK1: PC22 Remaining | AL1: PC42 Remaining
A2: HASLS22260801752 | B2: SWSR | C2: 2610N | D2: 202609170300 | F2: THBKK | G2: HKHKG | H2: 20'x1 | I2: BKK27 | J2: B.C. DEPOT CO.,LTD. ( Bang-Na KM.18) | K2: 20260905 | L2: CARDINAL MARITIME (THAILAND) CO., LTD. | M2: HERITAGE SNACKS & FOOD CO., LTD. | N2: NUTS | O2: Request food grade container | P2: Pickup : 2026-09-05, Return : 2026-09-07 *1ST RETURN CNTR DD.13/09/2026 WITHOUT RENT* | Q2: 1 | R2: 0 | S2: 0 | T2: 0 | U2: 0 | V2: 0 | W2: 0 | X2: 0 | Y2: 0 | Z2: 0 | AA2: 0 | AB2: =SUM(Q2:Y2)-Z2 -> 1 | AC2: =IF(I2="","",IF(OR(LEFT(I2,3)="BKK",I2="LCH55"),"BKK",IF(LEFT(I2,3)="LCH","LCH","OTHER"))) -> BKK | AD2: =MAX(0,Q2-MAX(0,Z2-0)) -> 1 | AE2: =MAX(0,R2-MAX(0,Z2-SUM(Q2:Q2))) -> 0 | AF2: =MAX(0,S2-MAX(0,Z2-SUM(Q2:R2))) -> 0 | AG2: =MAX(0,T2-MAX(0,Z2-SUM(Q2:S2))) -> 0 | AH2: =MAX(0,U2-MAX(0,Z2-SUM(Q2:T2))) -> 0 | AI2: =MAX(0,V2-MAX(0,Z2-SUM(Q2:U2))) -> 0 | AJ2: =MAX(0,W2-MAX(0,Z2-SUM(Q2:V2))) -> 0 | AK2: =MAX(0,X2-MAX(0,Z2-SUM(Q2:W2))) -> 0 | AL2: =MAX(0,Y2-MAX(0,Z2-SUM(Q2:X2))) -> 0
A3: HASLS22260802441 | B3: SWSR | C3: 2610N | D3: 202609170300 | F3: THBKK | G3: HKHKG | H3: 20'x1 | I3: BKK27 | J3: B.C. DEPOT CO.,LTD. ( Bang-Na KM.18) | K3: 20260908 | L3: QONATUS SERVICE CO., LTD. | M3: AB FOOD & BEVERAGES (THAILAND) LTD. | N3: BEVERAGE | O3: GOOD & CLEAN CNTR | P3: Pickup : 2026-09-08, Return : 2026-09-09 *1ST RETURN CNTR DD.13/09/2026* | Q3: 1 | R3: 0 | S3: 0 | T3: 0 | U3: 0 | V3: 0 | W3: 0 | X3: 0 | Y3: 0 | Z3: 0 | AA3: 0 | AB3: =SUM(Q3:Y3)-Z3 -> 1 | AC3: =IF(I3="","",IF(OR(LEFT(I3,3)="BKK",I3="LCH55"),"BKK",IF(LEFT(I3,3)="LCH","LCH","OTHER"))) -> BKK | AD3: =MAX(0,Q3-MAX(0,Z3-0)) -> 1 | AE3: =MAX(0,R3-MAX(0,Z3-SUM(Q3:Q3))) -> 0 | AF3: =MAX(0,S3-MAX(0,Z3-SUM(Q3:R3))) -> 0 | AG3: =MAX(0,T3-MAX(0,Z3-SUM(Q3:S3))) -> 0 | AH3: =MAX(0,U3-MAX(0,Z3-SUM(Q3:T3))) -> 0 | AI3: =MAX(0,V3-MAX(0,Z3-SUM(Q3:U3))) -> 0 | AJ3: =MAX(0,W3-MAX(0,Z3-SUM(Q3:V3))) -> 0 | AK3: =MAX(0,X3-MAX(0,Z3-SUM(Q3:W3))) -> 0 | AL3: =MAX(0,Y3-MAX(0,Z3-SUM(Q3:X3))) -> 0
A4: HASLS22260801713 | B4: SWCP | C4: 2609N | D4: 202609121200 | F4: THLCH | G4: JPYKK | H4: 20'x1 | I4: LCHY5 | J4: PW DEPOT CO., LTD. | K4: 20260901 | L4: DOW CHEMICAL THAILAND LTD. | M4: SIAM POLYETHYLENE CO., LTD. | N4: RESIN | O4: 1X20' SEABULK | P4: Pickup : 2026-09-01, Return : 2026-09-08 | Q4: 1 | R4: 0 | S4: 0 | T4: 0 | U4: 0 | V4: 0 | W4: 0 | X4: 0 | Y4: 0 | Z4: 0 | AA4: 0 | AB4: =SUM(Q4:Y4)-Z4 -> 1 | AC4: =IF(I4="","",IF(OR(LEFT(I4,3)="BKK",I4="LCH55"),"BKK",IF(LEFT(I4,3)="LCH","LCH","OTHER"))) -> LCH | AD4: =MAX(0,Q4-MAX(0,Z4-0)) -> 1 | AE4: =MAX(0,R4-MAX(0,Z4-SUM(Q4:Q4))) -> 0 | AF4: =MAX(0,S4-MAX(0,Z4-SUM(Q4:R4))) -> 0 | AG4: =MAX(0,T4-MAX(0,Z4-SUM(Q4:S4))) -> 0 | AH4: =MAX(0,U4-MAX(0,Z4-SUM(Q4:T4))) -> 0 | AI4: =MAX(0,V4-MAX(0,Z4-SUM(Q4:U4))) -> 0 | AJ4: =MAX(0,W4-MAX(0,Z4-SUM(Q4:V4))) -> 0 | AK4: =MAX(0,X4-MAX(0,Z4-SUM(Q4:W4))) -> 0 | AL4: =MAX(0,Y4-MAX(0,Z4-SUM(Q4:X4))) -> 0
A5: HASLS22260900144 | B5: SWSR | C5: 2610N | D5: 202609171400 | F5: THLCH | G5: HKHKG | H5: 20'x1 | I5: LCHY5 | J5: PW DEPOT CO., LTD. | K5: 20260907 | L5: IRPC PUBLIC COMPANY LIMITED | M5: IRPC PUBLIC COMPANY LIMITED | N5: RESIN | O5: GOOD AND CLEAN CTNR | P5: CY-RTN 07-08/09/26 (PI26050167-21) | Q5: 1 | R5: 0 | S5: 0 | T5: 0 | U5: 0 | V5: 0 | W5: 0 | X5: 0 | Y5: 0 | Z5: 0 | AA5: 0 | AB5: =SUM(Q5:Y5)-Z5 -> 1 | AC5: =IF(I5="","",IF(OR(LEFT(I5,3)="BKK",I5="LCH55"),"BKK",IF(LEFT(I5,3)="LCH","LCH","OTHER"))) -> LCH | AD5: =MAX(0,Q5-MAX(0,Z5-0)) -> 1 | AE5: =MAX(0,R5-MAX(0,Z5-SUM(Q5:Q5))) -> 0 | AF5: =MAX(0,S5-MAX(0,Z5-SUM(Q5:R5))) -> 0 | AG5: =MAX(0,T5-MAX(0,Z5-SUM(Q5:S5))) -> 0 | AH5: =MAX(0,U5-MAX(0,Z5-SUM(Q5:T5))) -> 0 | AI5: =MAX(0,V5-MAX(0,Z5-SUM(Q5:U5))) -> 0 | AJ5: =MAX(0,W5-MAX(0,Z5-SUM(Q5:V5))) -> 0 | AK5: =MAX(0,X5-MAX(0,Z5-SUM(Q5:W5))) -> 0 | AL5: =MAX(0,Y5-MAX(0,Z5-SUM(Q5:X5))) -> 0
A6: HASLS22260800345 | B6: SWSR | C6: 2610N | D6: 202609171400 | F6: THLCH | G6: HKHKG | H6: 20'x1 | I6: LCHY5 | J6: PW DEPOT CO., LTD. | K6: 20260907 | L6: CARGO CARE LOGISTICS CO., LTD. | M6: SIAM DEL MONTE CO., LTD. | N6: SWEET CORN | O6: Good and Clean Container (Food Grade) (No leaks, no odors, and no oil stains.) | P6: Pickup : 2026-09-07, Return : 2026-09-09 ** PLEASE CHECK OPEN GATE BEFORE RETURN CNTR ** | Q6: 1 | R6: 0 | S6: 0 | T6: 0 | U6: 0 | V6: 0 | W6: 0 | X6: 0 | Y6: 0 | Z6: 0 | AA6: 0 | AB6: =SUM(Q6:Y6)-Z6 -> 1 | AC6: =IF(I6="","",IF(OR(LEFT(I6,3)="BKK",I6="LCH55"),"BKK",IF(LEFT(I6,3)="LCH","LCH","OTHER"))) -> LCH | AD6: =MAX(0,Q6-MAX(0,Z6-0)) -> 1 | AE6: =MAX(0,R6-MAX(0,Z6-SUM(Q6:Q6))) -> 0 | AF6: =MAX(0,S6-MAX(0,Z6-SUM(Q6:R6))) -> 0 | AG6: =MAX(0,T6-MAX(0,Z6-SUM(Q6:S6))) -> 0 | AH6: =MAX(0,U6-MAX(0,Z6-SUM(Q6:T6))) -> 0 | AI6: =MAX(0,V6-MAX(0,Z6-SUM(Q6:U6))) -> 0 | AJ6: =MAX(0,W6-MAX(0,Z6-SUM(Q6:V6))) -> 0 | AK6: =MAX(0,X6-MAX(0,Z6-SUM(Q6:W6))) -> 0 | AL6: =MAX(0,Y6-MAX(0,Z6-SUM(Q6:X6))) -> 0
A7: HASLS22260601389 | B7: SWIC | C7: 2610N | D7: 202609221100 | F7: THBKK | G7: VNSGN | H7: 20'x1 | I7: BKK01 | J7: PAT TERMINAL 2 (PORT AUTHORITY OF THAILAND) | K7: 20260904 | L7: UNITED MARINE LOGISTIC CO., LTD. | M7: UNITED MARINE LOGISTIC CO., LTD. | N7: GENERAL CARGO (CONSOL) | O7: CONSOL | P7: Pickup : 2026-09-04, Return : 2026-09-04 (1ST RTN 05/09 W/O RENT) CLS TIME 06/09 @23.59 | Q7: 1 | R7: 0 | S7: 0 | T7: 0 | U7: 0 | V7: 0 | W7: 0 | X7: 0 | Y7: 0 | Z7: 0 | AA7: 0 | AB7: =SUM(Q7:Y7)-Z7 -> 1 | AC7: =IF(I7="","",IF(OR(LEFT(I7,3)="BKK",I7="LCH55"),"BKK",IF(LEFT(I7,3)="LCH","LCH","OTHER"))) -> BKK | AD7: =MAX(0,Q7-MAX(0,Z7-0)) -> 1 | AE7: =MAX(0,R7-MAX(0,Z7-SUM(Q7:Q7))) -> 0 | AF7: =MAX(0,S7-MAX(0,Z7-SUM(Q7:R7))) -> 0 | AG7: =MAX(0,T7-MAX(0,Z7-SUM(Q7:S7))) -> 0 | AH7: =MAX(0,U7-MAX(0,Z7-SUM(Q7:T7))) -> 0 | AI7: =MAX(0,V7-MAX(0,Z7-SUM(Q7:U7))) -> 0 | AJ7: =MAX(0,W7-MAX(0,Z7-SUM(Q7:V7))) -> 0 | AK7: =MAX(0,X7-MAX(0,Z7-SUM(Q7:W7))) -> 0 | AL7: =MAX(0,Y7-MAX(0,Z7-SUM(Q7:X7))) -> 0
A8: HASLS22260801718 | B8: SWCP | C8: 2609N | D8: 202609121200 | F8: THLCH | G8: JPYKK | H8: 20'x1 | I8: LCHY5 | J8: PW DEPOT CO., LTD. | K8: 20260901 | L8: DOW CHEMICAL THAILAND LTD. | M8: SIAM POLYETHYLENE CO., LTD. | N8: RESIN | O8: 1X20' SEABULK | P8: Pickup : 2026-09-01, Return : 2026-09-08 | Q8: 1 | R8: 0 | S8: 0 | T8: 0 | U8: 0 | V8: 0 | W8: 0 | X8: 0 | Y8: 0 | Z8: 0 | AA8: 0 | AB8: =SUM(Q8:Y8)-Z8 -> 1 | AC8: =IF(I8="","",IF(OR(LEFT(I8,3)="BKK",I8="LCH55"),"BKK",IF(LEFT(I8,3)="LCH","LCH","OTHER"))) -> LCH | AD8: =MAX(0,Q8-MAX(0,Z8-0)) -> 1 | AE8: =MAX(0,R8-MAX(0,Z8-SUM(Q8:Q8))) -> 0 | AF8: =MAX(0,S8-MAX(0,Z8-SUM(Q8:R8))) -> 0 | AG8: =MAX(0,T8-MAX(0,Z8-SUM(Q8:S8))) -> 0 | AH8: =MAX(0,U8-MAX(0,Z8-SUM(Q8:T8))) -> 0 | AI8: =MAX(0,V8-MAX(0,Z8-SUM(Q8:U8))) -> 0 | AJ8: =MAX(0,W8-MAX(0,Z8-SUM(Q8:V8))) -> 0 | AK8: =MAX(0,X8-MAX(0,Z8-SUM(Q8:W8))) -> 0 | AL8: =MAX(0,Y8-MAX(0,Z8-SUM(Q8:X8))) -> 0
A9: HASLS22260801624 | B9: SWSR | C9: 2610N | D9: 202609170300 | F9: THBKK | G9: HKHKG | H9: 20'x1 | I9: BKK27 | J9: B.C. DEPOT CO.,LTD. ( Bang-Na KM.18) | K9: 20260908 | L9: SONIC INTERFREIGHT PUBLIC COMPANY LIMITED | M9: THAI OTSUKA PHARMACEUTICAL CO., LTD. | N9: MEDICAL | O9: GOOD & CLEAN CONT. NO SMELL | P9: Pickup : 2026-09-08, Return : 2026-09-09 | Q9: 1 | R9: 0 | S9: 0 | T9: 0 | U9: 0 | V9: 0 | W9: 0 | X9: 0 | Y9: 0 | Z9: 0 | AA9: 0 | AB9: =SUM(Q9:Y9)-Z9 -> 1 | AC9: =IF(I9="","",IF(OR(LEFT(I9,3)="BKK",I9="LCH55"),"BKK",IF(LEFT(I9,3)="LCH","LCH","OTHER"))) -> BKK | AD9: =MAX(0,Q9-MAX(0,Z9-0)) -> 1 | AE9: =MAX(0,R9-MAX(0,Z9-SUM(Q9:Q9))) -> 0 | AF9: =MAX(0,S9-MAX(0,Z9-SUM(Q9:R9))) -> 0 | AG9: =MAX(0,T9-MAX(0,Z9-SUM(Q9:S9))) -> 0 | AH9: =MAX(0,U9-MAX(0,Z9-SUM(Q9:T9))) -> 0 | AI9: =MAX(0,V9-MAX(0,Z9-SUM(Q9:U9))) -> 0 | AJ9: =MAX(0,W9-MAX(0,Z9-SUM(Q9:V9))) -> 0 | AK9: =MAX(0,X9-MAX(0,Z9-SUM(Q9:W9))) -> 0 | AL9: =MAX(0,Y9-MAX(0,Z9-SUM(Q9:X9))) -> 0
A10: HASLS22260702326 | B10: SWSR | C10: 2610N | D10: 202609171400 | F10: THLCH | G10: HKHKG | H10: 20'x1 | I10: LCHY5 | J10: PW DEPOT CO., LTD. | K10: 20260827 | L10: THAI POLYCARBONATE CO., LTD. | M10: THAI POLYCARBONATE CO., LTD. | N10: POLYCARBONATE RESIN , HS CODEIS 3907.40 | O10: PLEASE PROVIDE GOOD AND CLEAN CONTAINER, NO RUST, NO HOLE, NO SMELL WITH STRONG FLOORBOARD (LOAD BY FORKLIFT) AND BULLET SEAL TO THIS SHIPMENT | P10: Pickup : 2026-08-27, Return : 2026-08-28 **CHECK OPENGATE BEFORE RETURN CNTR** | Q10: 1 | R10: 0 | S10: 0 | T10: 0 | U10: 0 | V10: 0 | W10: 0 | X10: 0 | Y10: 0 | Z10: 0 | AA10: 0 | AB10: =SUM(Q10:Y10)-Z10 -> 1 | AC10: =IF(I10="","",IF(OR(LEFT(I10,3)="BKK",I10="LCH55"),"BKK",IF(LEFT(I10,3)="LCH","LCH","OTHER"))) -> LCH | AD10: =MAX(0,Q10-MAX(0,Z10-0)) -> 1 | AE10: =MAX(0,R10-MAX(0,Z10-SUM(Q10:Q10))) -> 0 | AF10: =MAX(0,S10-MAX(0,Z10-SUM(Q10:R10))) -> 0 | AG10: =MAX(0,T10-MAX(0,Z10-SUM(Q10:S10))) -> 0 | AH10: =MAX(0,U10-MAX(0,Z10-SUM(Q10:T10))) -> 0 | AI10: =MAX(0,V10-MAX(0,Z10-SUM(Q10:U10))) -> 0 | AJ10: =MAX(0,W10-MAX(0,Z10-SUM(Q10:V10))) -> 0 | AK10: =MAX(0,X10-MAX(0,Z10-SUM(Q10:W10))) -> 0 | AL10: =MAX(0,Y10-MAX(0,Z10-SUM(Q10:X10))) -> 0
A11: HASLS22260801715 | B11: SWCP | C11: 2609N | D11: 202609121200 | F11: THLCH | G11: JPYKK | H11: 20'x1 | I11: LCHY5 | J11: PW DEPOT CO., LTD. | K11: 20260901 | L11: DOW CHEMICAL THAILAND LTD. | M11: SIAM POLYETHYLENE CO., LTD. | N11: RESIN | O11: 1X20' SEABULK | P11: Pickup : 2026-09-01, Return : 2026-09-08 | Q11: 1 | R11: 0 | S11: 0 | T11: 0 | U11: 0 | V11: 0 | W11: 0 | X11: 0 | Y11: 0 | Z11: 0 | AA11: 0 | AB11: =SUM(Q11:Y11)-Z11 -> 1 | AC11: =IF(I11="","",IF(OR(LEFT(I11,3)="BKK",I11="LCH55"),"BKK",IF(LEFT(I11,3)="LCH","LCH","OTHER"))) -> LCH | AD11: =MAX(0,Q11-MAX(0,Z11-0)) -> 1 | AE11: =MAX(0,R11-MAX(0,Z11-SUM(Q11:Q11))) -> 0 | AF11: =MAX(0,S11-MAX(0,Z11-SUM(Q11:R11))) -> 0 | AG11: =MAX(0,T11-MAX(0,Z11-SUM(Q11:S11))) -> 0 | AH11: =MAX(0,U11-MAX(0,Z11-SUM(Q11:T11))) -> 0 | AI11: =MAX(0,V11-MAX(0,Z11-SUM(Q11:U11))) -> 0 | AJ11: =MAX(0,W11-MAX(0,Z11-SUM(Q11:V11))) -> 0 | AK11: =MAX(0,X11-MAX(0,Z11-SUM(Q11:W11))) -> 0 | AL11: =MAX(0,Y11-MAX(0,Z11-SUM(Q11:X11))) -> 0
A12: HASLS22260801712 | B12: SWCP | C12: 2609N | D12: 202609121200 | F12: THLCH | G12: JPYKK | H12: 20'x1 | I12: LCHY5 | J12: PW DEPOT CO., LTD. | K12: 20260901 | L12: DOW CHEMICAL THAILAND LTD. | M12: SIAM POLYETHYLENE CO., LTD. | N12: RESIN | O12: 1X20' SEABULK | P12: Pickup : 2026-09-01, Return : 2026-09-08 | Q12: 1 | R12: 0 | S12: 0 | T12: 0 | U12: 0 | V12: 0 | W12: 0 | X12: 0 | Y12: 0 | Z12: 0 | AA12: 0 | AB12: =SUM(Q12:Y12)-Z12 -> 1 | AC12: =IF(I12="","",IF(OR(LEFT(I12,3)="BKK",I12="LCH55"),"BKK",IF(LEFT(I12,3)="LCH","LCH","OTHER"))) -> LCH | AD12: =MAX(0,Q12-MAX(0,Z12-0)) -> 1 | AE12: =MAX(0,R12-MAX(0,Z12-SUM(Q12:Q12))) -> 0 | AF12: =MAX(0,S12-MAX(0,Z12-SUM(Q12:R12))) -> 0 | AG12: =MAX(0,T12-MAX(0,Z12-SUM(Q12:S12))) -> 0 | AH12: =MAX(0,U12-MAX(0,Z12-SUM(Q12:T12))) -> 0 | AI12: =MAX(0,V12-MAX(0,Z12-SUM(Q12:U12))) -> 0 | AJ12: =MAX(0,W12-MAX(0,Z12-SUM(Q12:V12))) -> 0 | AK12: =MAX(0,X12-MAX(0,Z12-SUM(Q12:W12))) -> 0 | AL12: =MAX(0,Y12-MAX(0,Z12-SUM(Q12:X12))) -> 0
A13: HASLS22260801667 | B13: YSVY | C13: 2607N | D13: 202609150200 | F13: THLCH | G13: JPNGO | H13: 20'x1 | I13: LCHY5 | J13: PW DEPOT CO., LTD. | K13: 20260902 | L13: DOW CHEMICAL THAILAND LTD. | M13: SIAM POLYETHYLENE CO., LTD. | N13: RESIN | O13: 1X20' SEABULK | P13: Pickup : 2026-09-02, Return : 2026-09-08 | Q13: 1 | R13: 0 | S13: 0 | T13: 0 | U13: 0 | V13: 0 | W13: 0 | X13: 0 | Y13: 0 | Z13: 0 | AA13: 0 | AB13: =SUM(Q13:Y13)-Z13 -> 1 | AC13: =IF(I13="","",IF(OR(LEFT(I13,3)="BKK",I13="LCH55"),"BKK",IF(LEFT(I13,3)="LCH","LCH","OTHER"))) -> LCH | AD13: =MAX(0,Q13-MAX(0,Z13-0)) -> 1 | AE13: =MAX(0,R13-MAX(0,Z13-SUM(Q13:Q13))) -> 0 | AF13: =MAX(0,S13-MAX(0,Z13-SUM(Q13:R13))) -> 0 | AG13: =MAX(0,T13-MAX(0,Z13-SUM(Q13:S13))) -> 0 | AH13: =MAX(0,U13-MAX(0,Z13-SUM(Q13:T13))) -> 0 | AI13: =MAX(0,V13-MAX(0,Z13-SUM(Q13:U13))) -> 0 | AJ13: =MAX(0,W13-MAX(0,Z13-SUM(Q13:V13))) -> 0 | AK13: =MAX(0,X13-MAX(0,Z13-SUM(Q13:W13))) -> 0 | AL13: =MAX(0,Y13-MAX(0,Z13-SUM(Q13:X13))) -> 0
... A43: HASLS22260801018 | B43: SWCP | C43: 2609N | D43: 202609111900 | F43: THBKK | G43: JPKSM | H43: 20'x12 | I43: BKK25 | J43: Smart Logistics Service (Thailand ) Co.,Ltd. | K43: 20260908 | L43: MEGALOAD DEVELOPMENT LOGISTICS CO., LTD. | M43: FISHMEAL MARKETING DEVELOPMENT CO., LTD. | N43: THAILAND STEAM DRIED FISHMEAL | O43: **APPROVE BY SJUNKIM DD: 20/08/26** DG22GPx12 (CLS 9 / UN 2216) | P43: [FIX]**APPROVE BY SJUNKIM DD: 20/08/26** DG22GPx12 (CLS 9 / UN 2216) Pickup : 2026-09-08, Return : 2026-09-09 (CLS TIME 10/09/26 @23.59 , 1ST RTN DD: 09/09/26 WO/RENT) | Q43: 12 | R43: 0 | S43: 0 | T43: 0 | U43: 0 | V43: 0 | W43: 0 | X43: 0 | Y43: 0 | Z43: 10 | AA43: 0 | AB43: =SUM(Q43:Y43)-Z43 -> 2 | AC43: =IF(I43="","",IF(OR(LEFT(I43,3)="BKK",I43="LCH55"),"BKK",IF(LEFT(I43,3)="LCH","LCH","OTHER"))) -> BKK | AD43: =MAX(0,Q43-MAX(0,Z43-0)) -> 2 | AE43: =MAX(0,R43-MAX(0,Z43-SUM(Q43:Q43))) -> 0 | AF43: =MAX(0,S43-MAX(0,Z43-SUM(Q43:R43))) -> 0 | AG43: =MAX(0,T43-MAX(0,Z43-SUM(Q43:S43))) -> 0 | AH43: =MAX(0,U43-MAX(0,Z43-SUM(Q43:T43))) -> 0 | AI43: =MAX(0,V43-MAX(0,Z43-SUM(Q43:U43))) -> 0 | AJ43: =MAX(0,W43-MAX(0,Z43-SUM(Q43:V43))) -> 0 | AK43: =MAX(0,X43-MAX(0,Z43-SUM(Q43:W43))) -> 0 | AL43: =MAX(0,Y43-MAX(0,Z43-SUM(Q43:X43))) -> 0
A44: HASLS22260801433 | B44: NSSJ | C44: 2607S | D44: 202609222100 | E44: THLKR | F44: THLCH | G44: IDJKT | H44: 20'x2 | I44: BKK27 | J44: B.C. DEPOT CO.,LTD. ( Bang-Na KM.18) | K44: 20260904 | L44: SCGJWD LOGISTICS PUBLIC COMPANY LIMITED | M44: NORITAKE SCG PLASTER CO., LTD. | N44: MOULDING PLASTER | O44: good and clean cont., no oil, no rusty | P44: CY-RTN : 04-07/09/2026 Paperless Code 2835 Closing Time LKB 2026-09-27 @ 23.59 // REF : ** PT Indoporcelain ** | Q44: 2 | R44: 0 | S44: 0 | T44: 0 | U44: 0 | V44: 0 | W44: 0 | X44: 0 | Y44: 0 | Z44: 0 | AA44: 0 | AB44: =SUM(Q44:Y44)-Z44 -> 2 | AC44: =IF(I44="","",IF(OR(LEFT(I44,3)="BKK",I44="LCH55"),"BKK",IF(LEFT(I44,3)="LCH","LCH","OTHER"))) -> BKK | AD44: =MAX(0,Q44-MAX(0,Z44-0)) -> 2 | AE44: =MAX(0,R44-MAX(0,Z44-SUM(Q44:Q44))) -> 0 | AF44: =MAX(0,S44-MAX(0,Z44-SUM(Q44:R44))) -> 0 | AG44: =MAX(0,T44-MAX(0,Z44-SUM(Q44:S44))) -> 0 | AH44: =MAX(0,U44-MAX(0,Z44-SUM(Q44:T44))) -> 0 | AI44: =MAX(0,V44-MAX(0,Z44-SUM(Q44:U44))) -> 0 | AJ44: =MAX(0,W44-MAX(0,Z44-SUM(Q44:V44))) -> 0 | AK44: =MAX(0,X44-MAX(0,Z44-SUM(Q44:W44))) -> 0 | AL44: =MAX(0,Y44-MAX(0,Z44-SUM(Q44:X44))) -> 0
A45: HASLS22260900541 | B45: PGPO | C45: 2612N | D45: 202610120730 | F45: THBKK | G45: VNSGN | H45: 20'x2 | I45: BKK25 | J45: Smart Logistics Service (Thailand ) Co.,Ltd. | K45: 20260908 | L45: MERCURIAL LOGISTICS CO.,LTD | M45: UENO FINE CHEMICALS INDUSTRY (THAILAND) LTD. | N45: MALTITOL SYRUP | O45: GOOD AND CLEAN CONTAINER | P45: Pickup : 2026-09-08, Return : 2026-09-09 | Q45: 2 | R45: 0 | S45: 0 | T45: 0 | U45: 0 | V45: 0 | W45: 0 | X45: 0 | Y45: 0 | Z45: 0 | AA45: 0 | AB45: =SUM(Q45:Y45)-Z45 -> 2 | AC45: =IF(I45="","",IF(OR(LEFT(I45,3)="BKK",I45="LCH55"),"BKK",IF(LEFT(I45,3)="LCH","LCH","OTHER"))) -> BKK | AD45: =MAX(0,Q45-MAX(0,Z45-0)) -> 2 | AE45: =MAX(0,R45-MAX(0,Z45-SUM(Q45:Q45))) -> 0 | AF45: =MAX(0,S45-MAX(0,Z45-SUM(Q45:R45))) -> 0 | AG45: =MAX(0,T45-MAX(0,Z45-SUM(Q45:S45))) -> 0 | AH45: =MAX(0,U45-MAX(0,Z45-SUM(Q45:T45))) -> 0 | AI45: =MAX(0,V45-MAX(0,Z45-SUM(Q45:U45))) -> 0 | AJ45: =MAX(0,W45-MAX(0,Z45-SUM(Q45:V45))) -> 0 | AK45: =MAX(0,X45-MAX(0,Z45-SUM(Q45:W45))) -> 0 | AL45: =MAX(0,Y45-MAX(0,Z45-SUM(Q45:X45))) -> 0
A46: HASLS22260801621 | B46: SWSR | C46: 2610N | D46: 202609170300 | F46: THBKK | G46: HKHKG | H46: 20'x2 | I46: BKK27 | J46: B.C. DEPOT CO.,LTD. ( Bang-Na KM.18) | K46: 20260907 | L46: SONIC INTERFREIGHT PUBLIC COMPANY LIMITED | M46: THAI OTSUKA PHARMACEUTICAL CO., LTD. | N46: MEDICAL | O46: GOOD & CLEAN CONT. NO SMELL | P46: Pickup : 2026-09-07, Return : 2026-09-08 | Q46: 2 | R46: 0 | S46: 0 | T46: 0 | U46: 0 | V46: 0 | W46: 0 | X46: 0 | Y46: 0 | Z46: 0 | AA46: 0 | AB46: =SUM(Q46:Y46)-Z46 -> 2 | AC46: =IF(I46="","",IF(OR(LEFT(I46,3)="BKK",I46="LCH55"),"BKK",IF(LEFT(I46,3)="LCH","LCH","OTHER"))) -> BKK | AD46: =MAX(0,Q46-MAX(0,Z46-0)) -> 2 | AE46: =MAX(0,R46-MAX(0,Z46-SUM(Q46:Q46))) -> 0 | AF46: =MAX(0,S46-MAX(0,Z46-SUM(Q46:R46))) -> 0 | AG46: =MAX(0,T46-MAX(0,Z46-SUM(Q46:S46))) -> 0 | AH46: =MAX(0,U46-MAX(0,Z46-SUM(Q46:T46))) -> 0 | AI46: =MAX(0,V46-MAX(0,Z46-SUM(Q46:U46))) -> 0 | AJ46: =MAX(0,W46-MAX(0,Z46-SUM(Q46:V46))) -> 0 | AK46: =MAX(0,X46-MAX(0,Z46-SUM(Q46:W46))) -> 0 | AL46: =MAX(0,Y46-MAX(0,Z46-SUM(Q46:X46))) -> 0
A47: HASLS22260801987 | B47: KMSU | C47: 2607S | D47: 202609301500 | F47: THLCH | G47: IDJKT | H47: 20'x2 | I47: LCHY5 | J47: PW DEPOT CO., LTD. | K47: 20260822 | L47: L.A.1 CO.,LTD. | M47: TANATEX CHEMICALS (THAILAND) CO., LTD. | N47: CHEMICALS PRODUCT (NON DG) | O47: GOOD AND CLEAN CONTAINER | P47: Pickup : 2026-08-22, Return : 2026-08-24 | Q47: 2 | R47: 0 | S47: 0 | T47: 0 | U47: 0 | V47: 0 | W47: 0 | X47: 0 | Y47: 0 | Z47: 0 | AA47: 0 | AB47: =SUM(Q47:Y47)-Z47 -> 2 | AC47: =IF(I47="","",IF(OR(LEFT(I47,3)="BKK",I47="LCH55"),"BKK",IF(LEFT(I47,3)="LCH","LCH","OTHER"))) -> LCH | AD47: =MAX(0,Q47-MAX(0,Z47-0)) -> 2 | AE47: =MAX(0,R47-MAX(0,Z47-SUM(Q47:Q47))) -> 0 | AF47: =MAX(0,S47-MAX(0,Z47-SUM(Q47:R47))) -> 0 | AG47: =MAX(0,T47-MAX(0,Z47-SUM(Q47:S47))) -> 0 | AH47: =MAX(0,U47-MAX(0,Z47-SUM(Q47:T47))) -> 0 | AI47: =MAX(0,V47-MAX(0,Z47-SUM(Q47:U47))) -> 0 | AJ47: =MAX(0,W47-MAX(0,Z47-SUM(Q47:V47))) -> 0 | AK47: =MAX(0,X47-MAX(0,Z47-SUM(Q47:W47))) -> 0 | AL47: =MAX(0,Y47-MAX(0,Z47-SUM(Q47:X47))) -> 0
A48: HASLS22260900145 | B48: SWSR | C48: 2610N | D48: 202609171400 | F48: THLCH | G48: HKHKG | H48: 20'x2 | I48: LCHY5 | J48: PW DEPOT CO., LTD. | K48: 20260907 | L48: IRPC PUBLIC COMPANY LIMITED | M48: IRPC PUBLIC COMPANY LIMITED | N48: RESIN | O48: GOOD AND CLEAN CTNR | P48: CY-RTN 07-08/09/26 (PI26050167-22) | Q48: 2 | R48: 0 | S48: 0 | T48: 0 | U48: 0 | V48: 0 | W48: 0 | X48: 0 | Y48: 0 | Z48: 0 | AA48: 0 | AB48: =SUM(Q48:Y48)-Z48 -> 2 | AC48: =IF(I48="","",IF(OR(LEFT(I48,3)="BKK",I48="LCH55"),"BKK",IF(LEFT(I48,3)="LCH","LCH","OTHER"))) -> LCH | AD48: =MAX(0,Q48-MAX(0,Z48-0)) -> 2 | AE48: =MAX(0,R48-MAX(0,Z48-SUM(Q48:Q48))) -> 0 | AF48: =MAX(0,S48-MAX(0,Z48-SUM(Q48:R48))) -> 0 | AG48: =MAX(0,T48-MAX(0,Z48-SUM(Q48:S48))) -> 0 | AH48: =MAX(0,U48-MAX(0,Z48-SUM(Q48:T48))) -> 0 | AI48: =MAX(0,V48-MAX(0,Z48-SUM(Q48:U48))) -> 0 | AJ48: =MAX(0,W48-MAX(0,Z48-SUM(Q48:V48))) -> 0 | AK48: =MAX(0,X48-MAX(0,Z48-SUM(Q48:W48))) -> 0 | AL48: =MAX(0,Y48-MAX(0,Z48-SUM(Q48:X48))) -> 0
A49: HASLS22260800103 | B49: SWIC | C49: 2610N | D49: 202609221100 | F49: THBKK | G49: VNSGN | H49: 20'x2 | I49: BKK27 | J49: B.C. DEPOT CO.,LTD. ( Bang-Na KM.18) | K49: 20260815 | L49: QUANTERM LOGISTICS (THAILAND) CO., LTD. | M49: THAI GYPSUM PRODUCTS PCL. | N49: GYPSUM PLASTER - 25202090 | O49: GOOD AND CLEAN CONTAINER | P49: Pickup : 2026-08-15, Return : 2026-08-17 (1ST RTN DD: 18/09/26 WO/RENT) | Q49: 2 | R49: 0 | S49: 0 | T49: 0 | U49: 0 | V49: 0 | W49: 0 | X49: 0 | Y49: 0 | Z49: 0 | AA49: 0 | AB49: =SUM(Q49:Y49)-Z49 -> 2 | AC49: =IF(I49="","",IF(OR(LEFT(I49,3)="BKK",I49="LCH55"),"BKK",IF(LEFT(I49,3)="LCH","LCH","OTHER"))) -> BKK | AD49: =MAX(0,Q49-MAX(0,Z49-0)) -> 2 | AE49: =MAX(0,R49-MAX(0,Z49-SUM(Q49:Q49))) -> 0 | AF49: =MAX(0,S49-MAX(0,Z49-SUM(Q49:R49))) -> 0 | AG49: =MAX(0,T49-MAX(0,Z49-SUM(Q49:S49))) -> 0 | AH49: =MAX(0,U49-MAX(0,Z49-SUM(Q49:T49))) -> 0 | AI49: =MAX(0,V49-MAX(0,Z49-SUM(Q49:U49))) -> 0 | AJ49: =MAX(0,W49-MAX(0,Z49-SUM(Q49:V49))) -> 0 | AK49: =MAX(0,X49-MAX(0,Z49-SUM(Q49:W49))) -> 0 | AL49: =MAX(0,Y49-MAX(0,Z49-SUM(Q49:X49))) -> 0
A50: HASLS22260701999 | B50: SWSR | C50: 2610N | D50: 202609170300 | F50: THBKK | G50: CNXMN | H50: 20'x3 | I50: BKK27 | J50: B.C. DEPOT CO.,LTD. ( Bang-Na KM.18) | K50: 20260908 | L50: DIMERCO EXPRESS (THAILAND) CO., LTD. | M50: ASIA MODIFIED STARCH CO., LTD. | N50: STARCH | O50: Dry & Clean Container (Food Grade) / Container grade A | P50: Pickup : 2026-09-08, Return : 2026-09-11 | Q50: 3 | R50: 0 | S50: 0 | T50: 0 | U50: 0 | V50: 0 | W50: 0 | X50: 0 | Y50: 0 | Z50: 0 | AA50: 0 | AB50: =SUM(Q50:Y50)-Z50 -> 3 | AC50: =IF(I50="","",IF(OR(LEFT(I50,3)="BKK",I50="LCH55"),"BKK",IF(LEFT(I50,3)="LCH","LCH","OTHER"))) -> BKK | AD50: =MAX(0,Q50-MAX(0,Z50-0)) -> 3 | AE50: =MAX(0,R50-MAX(0,Z50-SUM(Q50:Q50))) -> 0 | AF50: =MAX(0,S50-MAX(0,Z50-SUM(Q50:R50))) -> 0 | AG50: =MAX(0,T50-MAX(0,Z50-SUM(Q50:S50))) -> 0 | AH50: =MAX(0,U50-MAX(0,Z50-SUM(Q50:T50))) -> 0 | AI50: =MAX(0,V50-MAX(0,Z50-SUM(Q50:U50))) -> 0 | AJ50: =MAX(0,W50-MAX(0,Z50-SUM(Q50:V50))) -> 0 | AK50: =MAX(0,X50-MAX(0,Z50-SUM(Q50:W50))) -> 0 | AL50: =MAX(0,Y50-MAX(0,Z50-SUM(Q50:X50))) -> 0
A51: HASLS22260900416 | B51: SWBT | C51: 2615N | D51: 202609210600 | F51: THLCH | G51: VNSGN | H51: 40Hx1 | K51: 20260908 | L51: QUANTERM LOGISTICS (THAILAND) CO., LTD. | M51: AMPLUSCHEM CO., LTD. | N51: BLACK PEPPER GRIND | O51: GOOD AND CLEAN CONTAINER | P51: Pickup : 2026-09-08, Return : 2026-09-08 | Q51: 0 | R51: 0 | S51: 1 | T51: 0 | U51: 0 | V51: 0 | W51: 0 | X51: 0 | Y51: 0 | Z51: 0 | AA51: 0 | AB51: =SUM(Q51:Y51)-Z51 -> 1 | AC51: =IF(I51="","",IF(OR(LEFT(I51,3)="BKK",I51="LCH55"),"BKK",IF(LEFT(I51,3)="LCH","LCH","OTHER"))) | AD51: =MAX(0,Q51-MAX(0,Z51-0)) -> 0 | AE51: =MAX(0,R51-MAX(0,Z51-SUM(Q51:Q51))) -> 0 | AF51: =MAX(0,S51-MAX(0,Z51-SUM(Q51:R51))) -> 1 | AG51: =MAX(0,T51-MAX(0,Z51-SUM(Q51:S51))) -> 0 | AH51: =MAX(0,U51-MAX(0,Z51-SUM(Q51:T51))) -> 0 | AI51: =MAX(0,V51-MAX(0,Z51-SUM(Q51:U51))) -> 0 | AJ51: =MAX(0,W51-MAX(0,Z51-SUM(Q51:V51))) -> 0 | AK51: =MAX(0,X51-MAX(0,Z51-SUM(Q51:W51))) -> 0 | AL51: =MAX(0,Y51-MAX(0,Z51-SUM(Q51:X51))) -> 0
A52: HASLS22260801876 | B52: SWSR | C52: 2610N | D52: 202609170300 | F52: THBKK | G52: HKHKG | H52: 40Hx1 | I52: BKK01 | J52: PAT TERMINAL 2 (PORT AUTHORITY OF THAILAND) | K52: 20260907 | L52: HANDLE INTER CONSOLIDATION CO., LTD. | M52: HANDLE INTER CONSOLIDATION CO., LTD. | N52: GENERAL CARGO | O52: CONSOL | P52: Pickup : 2026-09-07, Return : 2026-09-09 CONSOL | Q52: 0 | R52: 0 | S52: 1 | T52: 0 | U52: 0 | V52: 0 | W52: 0 | X52: 0 | Y52: 0 | Z52: 0 | AA52: 0 | AB52: =SUM(Q52:Y52)-Z52 -> 1 | AC52: =IF(I52="","",IF(OR(LEFT(I52,3)="BKK",I52="LCH55"),"BKK",IF(LEFT(I52,3)="LCH","LCH","OTHER"))) -> BKK | AD52: =MAX(0,Q52-MAX(0,Z52-0)) -> 0 | AE52: =MAX(0,R52-MAX(0,Z52-SUM(Q52:Q52))) -> 0 | AF52: =MAX(0,S52-MAX(0,Z52-SUM(Q52:R52))) -> 1 | AG52: =MAX(0,T52-MAX(0,Z52-SUM(Q52:S52))) -> 0 | AH52: =MAX(0,U52-MAX(0,Z52-SUM(Q52:T52))) -> 0 | AI52: =MAX(0,V52-MAX(0,Z52-SUM(Q52:U52))) -> 0 | AJ52: =MAX(0,W52-MAX(0,Z52-SUM(Q52:V52))) -> 0 | AK52: =MAX(0,X52-MAX(0,Z52-SUM(Q52:W52))) -> 0 | AL52: =MAX(0,Y52-MAX(0,Z52-SUM(Q52:X52))) -> 0
A53: HASLS22260801132 | B53: SWMM | C53: 2609N | D53: 202609230700 | F53: THBKK | G53: JPMYJ | H53: 40Hx1 | I53: BKK27 | J53: B.C. DEPOT CO.,LTD. ( Bang-Na KM.18) | K53: 20260908 | L53: C.P. INTERTRADE CO., LTD. | M53: PERFECT COMPANION GROUP CO., LTD. | N53: PET FOOD | O53: REQ CLEAN AND GOOD CNTR STRONG FLOOR | P53: Pickup : 2026-09-08, Return : 2026-09-09 | Q53: 0 | R53: 0 | S53: 1 | T53: 0 | U53: 0 | V53: 0 | W53: 0 | X53: 0 | Y53: 0 | Z53: 0 | AA53: 0 | AB53: =SUM(Q53:Y53)-Z53 -> 1 | AC53: =IF(I53="","",IF(OR(LEFT(I53,3)="BKK",I53="LCH55"),"BKK",IF(LEFT(I53,3)="LCH","LCH","OTHER"))) -> BKK | AD53: =MAX(0,Q53-MAX(0,Z53-0)) -> 0 | AE53: =MAX(0,R53-MAX(0,Z53-SUM(Q53:Q53))) -> 0 | AF53: =MAX(0,S53-MAX(0,Z53-SUM(Q53:R53))) -> 1 | AG53: =MAX(0,T53-MAX(0,Z53-SUM(Q53:S53))) -> 0 | AH53: =MAX(0,U53-MAX(0,Z53-SUM(Q53:T53))) -> 0 | AI53: =MAX(0,V53-MAX(0,Z53-SUM(Q53:U53))) -> 0 | AJ53: =MAX(0,W53-MAX(0,Z53-SUM(Q53:V53))) -> 0 | AK53: =MAX(0,X53-MAX(0,Z53-SUM(Q53:W53))) -> 0 | AL53: =MAX(0,Y53-MAX(0,Z53-SUM(Q53:X53))) -> 0
A54: HASLS22260900147 | B54: SWSR | C54: 2610N | D54: 202609170300 | F54: THBKK | G54: HKHKG | H54: 40Hx1 | I54: BKK25 | J54: Smart Logistics Service (Thailand ) Co.,Ltd. | K54: 20260903 | L54: PRO 3 BUILD INTERNATIONAL CO., LTD. | M54: ASK ME CO.,LTD | N54: TOYS | O54: GOOD AND CLEAN CONTAINER | P54: Pickup : 2026-09-03, Return : 2026-09-04 (1ST RTN DD: 09/09/26 WO/RENT) | Q54: 0 | R54: 0 | S54: 1 | T54: 0 | U54: 0 | V54: 0 | W54: 0 | X54: 0 | Y54: 0 | Z54: 0 | AA54: 0 | AB54: =SUM(Q54:Y54)-Z54 -> 1 | AC54: =IF(I54="","",IF(OR(LEFT(I54,3)="BKK",I54="LCH55"),"BKK",IF(LEFT(I54,3)="LCH","LCH","OTHER"))) -> BKK | AD54: =MAX(0,Q54-MAX(0,Z54-0)) -> 0 | AE54: =MAX(0,R54-MAX(0,Z54-SUM(Q54:Q54))) -> 0 | AF54: =MAX(0,S54-MAX(0,Z54-SUM(Q54:R54))) -> 1 | AG54: =MAX(0,T54-MAX(0,Z54-SUM(Q54:S54))) -> 0 | AH54: =MAX(0,U54-MAX(0,Z54-SUM(Q54:T54))) -> 0 | AI54: =MAX(0,V54-MAX(0,Z54-SUM(Q54:U54))) -> 0 | AJ54: =MAX(0,W54-MAX(0,Z54-SUM(Q54:V54))) -> 0 | AK54: =MAX(0,X54-MAX(0,Z54-SUM(Q54:W54))) -> 0 | AL54: =MAX(0,Y54-MAX(0,Z54-SUM(Q54:X54))) -> 0
A55: HASLS22260802380 | B55: KUS | C55: 2615N | D55: 202609212300 | F55: THBKK | G55: KRINC | H55: 40Hx1 | I55: BKK27 | J55: B.C. DEPOT CO.,LTD. ( Bang-Na KM.18) | K55: 20260903 | L55: JGL WORLDWIDE (THAILAND) CO., LTD. | M55: ASIAN FOODS CO.,LTD. | N55: KRISPY ROLL | O55: GOOD AND CLEAN CONTAINER | P55: Pickup : 2026-09-03, Return : 2026-09-04 (1ST RTN DD: 17/09/26 WO/RENT) | Q55: 0 | R55: 0 | S55: 1 | T55: 0 | U55: 0 | V55: 0 | W55: 0 | X55: 0 | Y55: 0 | Z55: 0 | AA55: 0 | AB55: =SUM(Q55:Y55)-Z55 -> 1 | AC55: =IF(I55="","",IF(OR(LEFT(I55,3)="BKK",I55="LCH55"),"BKK",IF(LEFT(I55,3)="LCH","LCH","OTHER"))) -> BKK | AD55: =MAX(0,Q55-MAX(0,Z55-0)) -> 0 | AE55: =MAX(0,R55-MAX(0,Z55-SUM(Q55:Q55))) -> 0 | AF55: =MAX(0,S55-MAX(0,Z55-SUM(Q55:R55))) -> 1 | AG55: =MAX(0,T55-MAX(0,Z55-SUM(Q55:S55))) -> 0 | AH55: =MAX(0,U55-MAX(0,Z55-SUM(Q55:T55))) -> 0 | AI55: =MAX(0,V55-MAX(0,Z55-SUM(Q55:U55))) -> 0 | AJ55: =MAX(0,W55-MAX(0,Z55-SUM(Q55:V55))) -> 0 | AK55: =MAX(0,X55-MAX(0,Z55-SUM(Q55:W55))) -> 0 | AL55: =MAX(0,Y55-MAX(0,Z55-SUM(Q55:X55))) -> 0
A56: HASLS22260900265 | B56: YSVY | C56: 2607N | D56: 202609150200 | E56: THSRP | F56: THLCH | G56: CNSHA | H56: 40Hx1 | I56: BKK25 | J56: Smart Logistics Service (Thailand ) Co.,Ltd. | K56: 20260907 | L56: THAIGO LOGISTICS CO.,LTD | M56: VAST OCEAN CO., LTD. | N56: HIPS RECYCLE PELLET | O56: RQST CNTR 32.5 TONS // 40'HQ | P56: Pickup : 2026-09-07, Return SRP : 2026-09-08 [PAPERLESS CODE 2829] CLS TIME 11/09/26 @23.59 | Q56: 0 | R56: 0 | S56: 1 | T56: 0 | U56: 0 | V56: 0 | W56: 0 | X56: 0 | Y56: 0 | Z56: 0 | AA56: 0 | AB56: =SUM(Q56:Y56)-Z56 -> 1 | AC56: =IF(I56="","",IF(OR(LEFT(I56,3)="BKK",I56="LCH55"),"BKK",IF(LEFT(I56,3)="LCH","LCH","OTHER"))) -> BKK | AD56: =MAX(0,Q56-MAX(0,Z56-0)) -> 0 | AE56: =MAX(0,R56-MAX(0,Z56-SUM(Q56:Q56))) -> 0 | AF56: =MAX(0,S56-MAX(0,Z56-SUM(Q56:R56))) -> 1 | AG56: =MAX(0,T56-MAX(0,Z56-SUM(Q56:S56))) -> 0 | AH56: =MAX(0,U56-MAX(0,Z56-SUM(Q56:T56))) -> 0 | AI56: =MAX(0,V56-MAX(0,Z56-SUM(Q56:U56))) -> 0 | AJ56: =MAX(0,W56-MAX(0,Z56-SUM(Q56:V56))) -> 0 | AK56: =MAX(0,X56-MAX(0,Z56-SUM(Q56:W56))) -> 0 | AL56: =MAX(0,Y56-MAX(0,Z56-SUM(Q56:X56))) -> 0
A57: HASLS22260702337 | B57: DJCF | C57: 0151N | D57: 202609190600 | F57: THLCH | G57: KRPTK | H57: 40Hx1 | I57: LCHY5 | J57: PW DEPOT CO., LTD. | K57: 20260908 | L57: SDS-ACUTECH CO., LTD. | M57: 3AC (THAILAND) CO., LTD. | N57: AIR PURIFIER | O57: GOOD AND CLEAN CONTAINER | P57: Pickup : 2026-09-08, Return : 2026-09-08 | Q57: 0 | R57: 0 | S57: 1 | T57: 0 | U57: 0 | V57: 0 | W57: 0 | X57: 0 | Y57: 0 | Z57: 0 | AA57: 0 | AB57: =SUM(Q57:Y57)-Z57 -> 1 | AC57: =IF(I57="","",IF(OR(LEFT(I57,3)="BKK",I57="LCH55"),"BKK",IF(LEFT(I57,3)="LCH","LCH","OTHER"))) -> LCH | AD57: =MAX(0,Q57-MAX(0,Z57-0)) -> 0 | AE57: =MAX(0,R57-MAX(0,Z57-SUM(Q57:Q57))) -> 0 | AF57: =MAX(0,S57-MAX(0,Z57-SUM(Q57:R57))) -> 1 | AG57: =MAX(0,T57-MAX(0,Z57-SUM(Q57:S57))) -> 0 | AH57: =MAX(0,U57-MAX(0,Z57-SUM(Q57:T57))) -> 0 | AI57: =MAX(0,V57-MAX(0,Z57-SUM(Q57:U57))) -> 0 | AJ57: =MAX(0,W57-MAX(0,Z57-SUM(Q57:V57))) -> 0 | AK57: =MAX(0,X57-MAX(0,Z57-SUM(Q57:W57))) -> 0 | AL57: =MAX(0,Y57-MAX(0,Z57-SUM(Q57:X57))) -> 0
A58: HASLS22260900251 | B58: SWCP | C58: 2609N | D58: 202609111900 | F58: THBKK | G58: VNSGN | H58: 40Hx1 | I58: BKK25 | J58: Smart Logistics Service (Thailand ) Co.,Ltd. | K58: 20260908 | L58: RTN LOGISTICS CO., LTD. | M58: CHIA TAI SEEDS CO., LTD. | N58: VEGETABLE SEEDS FOR SOWING PURPOSE | O58: ** REQUEST GOOD & CLEAN GRADE A CONTAINER FOR SEEDS CARGO** | P58: Pickup : 2026-09-08, Return : 2026-09-09 | Q58: 0 | R58: 0 | S58: 1 | T58: 0 | U58: 0 | V58: 0 | W58: 0 | X58: 0 | Y58: 0 | Z58: 0 | AA58: 0 | AB58: =SUM(Q58:Y58)-Z58 -> 1 | AC58: =IF(I58="","",IF(OR(LEFT(I58,3)="BKK",I58="LCH55"),"BKK",IF(LEFT(I58,3)="LCH","LCH","OTHER"))) -> BKK | AD58: =MAX(0,Q58-MAX(0,Z58-0)) -> 0 | AE58: =MAX(0,R58-MAX(0,Z58-SUM(Q58:Q58))) -> 0 | AF58: =MAX(0,S58-MAX(0,Z58-SUM(Q58:R58))) -> 1 | AG58: =MAX(0,T58-MAX(0,Z58-SUM(Q58:S58))) -> 0 | AH58: =MAX(0,U58-MAX(0,Z58-SUM(Q58:T58))) -> 0 | AI58: =MAX(0,V58-MAX(0,Z58-SUM(Q58:U58))) -> 0 | AJ58: =MAX(0,W58-MAX(0,Z58-SUM(Q58:V58))) -> 0 | AK58: =MAX(0,X58-MAX(0,Z58-SUM(Q58:W58))) -> 0 | AL58: =MAX(0,Y58-MAX(0,Z58-SUM(Q58:X58))) -> 0
A59: HASLS22260900181 | B59: SWSR | C59: 2610N | D59: 202609170300 | F59: THBKK | G59: HKHKG | H59: 40Hx1 | I59: BKK01 | J59: PAT TERMINAL 2 (PORT AUTHORITY OF THAILAND) | K59: 20260907 | L59: QUALITY ACCESS GLOBAL LOGISTICS CO., LTD | M59: QUALITY ACCESS GLOBAL LOGISTICS CO., LTD | N59: CONSOL | O59: CONSOL | P59: Pickup : 2026-09-07, Return : 2026-09-11 CONSOL | Q59: 0 | R59: 0 | S59: 1 | T59: 0 | U59: 0 | V59: 0 | W59: 0 | X59: 0 | Y59: 0 | Z59: 0 | AA59: 0 | AB59: =SUM(Q59:Y59)-Z59 -> 1 | AC59: =IF(I59="","",IF(OR(LEFT(I59,3)="BKK",I59="LCH55"),"BKK",IF(LEFT(I59,3)="LCH","LCH","OTHER"))) -> BKK | AD59: =MAX(0,Q59-MAX(0,Z59-0)) -> 0 | AE59: =MAX(0,R59-MAX(0,Z59-SUM(Q59:Q59))) -> 0 | AF59: =MAX(0,S59-MAX(0,Z59-SUM(Q59:R59))) -> 1 | AG59: =MAX(0,T59-MAX(0,Z59-SUM(Q59:S59))) -> 0 | AH59: =MAX(0,U59-MAX(0,Z59-SUM(Q59:T59))) -> 0 | AI59: =MAX(0,V59-MAX(0,Z59-SUM(Q59:U59))) -> 0 | AJ59: =MAX(0,W59-MAX(0,Z59-SUM(Q59:V59))) -> 0 | AK59: =MAX(0,X59-MAX(0,Z59-SUM(Q59:W59))) -> 0 | AL59: =MAX(0,Y59-MAX(0,Z59-SUM(Q59:X59))) -> 0
A60: HASLS22260801889 | B60: ICVY | C60: 2607S | D60: 202609191300 | F60: THLCH | G60: IDJKT | H60: 40Hx1 | I60: LCH28 | J60: CELLO | K60: 20260908 | L60: ILOGS GLOBAL CO.,LTD. | M60: MAJESTY HOLDINGS (ASIA) CO.,LTD. | N60: PIPE | O60: GOOD AND CLEAN CONTAINER | P60: Pickup : 2026-09-08, Return : 2026-09-08 | Q60: 0 | R60: 0 | S60: 1 | T60: 0 | U60: 0 | V60: 0 | W60: 0 | X60: 0 | Y60: 0 | Z60: 0 | AA60: 0 | AB60: =SUM(Q60:Y60)-Z60 -> 1 | AC60: =IF(I60="","",IF(OR(LEFT(I60,3)="BKK",I60="LCH55"),"BKK",IF(LEFT(I60,3)="LCH","LCH","OTHER"))) -> LCH | AD60: =MAX(0,Q60-MAX(0,Z60-0)) -> 0 | AE60: =MAX(0,R60-MAX(0,Z60-SUM(Q60:Q60))) -> 0 | AF60: =MAX(0,S60-MAX(0,Z60-SUM(Q60:R60))) -> 1 | AG60: =MAX(0,T60-MAX(0,Z60-SUM(Q60:S60))) -> 0 | AH60: =MAX(0,U60-MAX(0,Z60-SUM(Q60:T60))) -> 0 | AI60: =MAX(0,V60-MAX(0,Z60-SUM(Q60:U60))) -> 0 | AJ60: =MAX(0,W60-MAX(0,Z60-SUM(Q60:V60))) -> 0 | AK60: =MAX(0,X60-MAX(0,Z60-SUM(Q60:W60))) -> 0 | AL60: =MAX(0,Y60-MAX(0,Z60-SUM(Q60:X60))) -> 0
A61: HASLS22260800573 | B61: DJCF | C61: 0151N | D61: 202609190600 | F61: THLCH | G61: KRPUS | H61: 40Hx1 | I61: LCH27 | J61: HAST Logistics Co.,Ltd. | K61: 20260905 | L61: TRUE MARINE CO., LTD. | M61: INOAC (THAILAND) CO., LTD. | N61: POLYURETHANE FOAM | O61: **REQUEST GOOD AND CLEAN CONTAINER** | P61: Pickup : 2026-09-05, Return : 2026-09-07 // FM SWSR 2610N BY HAL DD.07/09 (1ST RETURN 14/09 W/O RENT) | Q61: 0 | R61: 0 | S61: 1 | T61: 0 | U61: 0 | V61: 0 | W61: 0 | X61: 0 | Y61: 0 | Z61: 0 | AA61: 0 | AB61: =SUM(Q61:Y61)-Z61 -> 1 | AC61: =IF(I61="","",IF(OR(LEFT(I61,3)="BKK",I61="LCH55"),"BKK",IF(LEFT(I61,3)="LCH","LCH","OTHER"))) -> LCH | AD61: =MAX(0,Q61-MAX(0,Z61-0)) -> 0 | AE61: =MAX(0,R61-MAX(0,Z61-SUM(Q61:Q61))) -> 0 | AF61: =MAX(0,S61-MAX(0,Z61-SUM(Q61:R61))) -> 1 | AG61: =MAX(0,T61-MAX(0,Z61-SUM(Q61:S61))) -> 0 | AH61: =MAX(0,U61-MAX(0,Z61-SUM(Q61:T61))) -> 0 | AI61: =MAX(0,V61-MAX(0,Z61-SUM(Q61:U61))) -> 0 | AJ61: =MAX(0,W61-MAX(0,Z61-SUM(Q61:V61))) -> 0 | AK61: =MAX(0,X61-MAX(0,Z61-SUM(Q61:W61))) -> 0 | AL61: =MAX(0,Y61-MAX(0,Z61-SUM(Q61:X61))) -> 0
A62: HASLS22260900696 | B62: SWAL | C62: 2608N | D62: 202609281500 | F62: THBKK | G62: VNSGN | H62: 40Hx1 | I62: BKK27 | J62: B.C. DEPOT CO.,LTD. ( Bang-Na KM.18) | K62: 20260825 | L62: FREIGHT LINKS EXPRESS (THAILAND) CO., LTD. | M62: FEDERAL-MOGUL (THAILAND) COMPANY LIMITED | N62: EMPTY PLASTIC BOBBIN | O62: GOOD AND CLEAN CONTAINER | P62: Pickup : 2026-08-25, Return : 2026-08-26 | Q62: 0 | R62: 0 | S62: 1 | T62: 0 | U62: 0 | V62: 0 | W62: 0 | X62: 0 | Y62: 0 | Z62: 0 | AA62: 0 | AB62: =SUM(Q62:Y62)-Z62 -> 1 | AC62: =IF(I62="","",IF(OR(LEFT(I62,3)="BKK",I62="LCH55"),"BKK",IF(LEFT(I62,3)="LCH","LCH","OTHER"))) -> BKK | AD62: =MAX(0,Q62-MAX(0,Z62-0)) -> 0 | AE62: =MAX(0,R62-MAX(0,Z62-SUM(Q62:Q62))) -> 0 | AF62: =MAX(0,S62-MAX(0,Z62-SUM(Q62:R62))) -> 1 | AG62: =MAX(0,T62-MAX(0,Z62-SUM(Q62:S62))) -> 0 | AH62: =MAX(0,U62-MAX(0,Z62-SUM(Q62:T62))) -> 0 | AI62: =MAX(0,V62-MAX(0,Z62-SUM(Q62:U62))) -> 0 | AJ62: =MAX(0,W62-MAX(0,Z62-SUM(Q62:V62))) -> 0 | AK62: =MAX(0,X62-MAX(0,Z62-SUM(Q62:W62))) -> 0 | AL62: =MAX(0,Y62-MAX(0,Z62-SUM(Q62:X62))) -> 0
A63: HASLS22260801939 | B63: SWBT | C63: 2615N | D63: 202609201200 | F63: THBKK | G63: VNSGN | H63: 40Hx1 | I63: BKK27 | J63: B.C. DEPOT CO.,LTD. ( Bang-Na KM.18) | K63: 20260905 | L63: QUANTERM LOGISTICS (THAILAND) CO., LTD. | M63: VISTA DISTRIBUTION CO.,LTD. | N63: SNACK | O63: GOOD AND CLEAN CONTAINER | P63: Pickup : 2026-09-05, Return : 2026-09-07 (1ST RTN DD: 13/09/26 WO/RENT) | Q63: 0 | R63: 0 | S63: 1 | T63: 0 | U63: 0 | V63: 0 | W63: 0 | X63: 0 | Y63: 0 | Z63: 0 | AA63: 0 | AB63: =SUM(Q63:Y63)-Z63 -> 1 | AC63: =IF(I63="","",IF(OR(LEFT(I63,3)="BKK",I63="LCH55"),"BKK",IF(LEFT(I63,3)="LCH","LCH","OTHER"))) -> BKK | AD63: =MAX(0,Q63-MAX(0,Z63-0)) -> 0 | AE63: =MAX(0,R63-MAX(0,Z63-SUM(Q63:Q63))) -> 0 | AF63: =MAX(0,S63-MAX(0,Z63-SUM(Q63:R63))) -> 1 | AG63: =MAX(0,T63-MAX(0,Z63-SUM(Q63:S63))) -> 0 | AH63: =MAX(0,U63-MAX(0,Z63-SUM(Q63:T63))) -> 0 | AI63: =MAX(0,V63-MAX(0,Z63-SUM(Q63:U63))) -> 0 | AJ63: =MAX(0,W63-MAX(0,Z63-SUM(Q63:V63))) -> 0 | AK63: =MAX(0,X63-MAX(0,Z63-SUM(Q63:W63))) -> 0 | AL63: =MAX(0,Y63-MAX(0,Z63-SUM(Q63:X63))) -> 0
A64: HASLS22260800736 | B64: SWMM | C64: 2609N | D64: 202609240000 | F64: THLCH | G64: KRPTK | H64: 40Hx1 | I64: LCHY5 | J64: PW DEPOT CO., LTD. | K64: 20260908 | L64: SDS-ACUTECH CO., LTD. | M64: 3AC (THAILAND) CO., LTD. | N64: AIR PURIFIER | O64: GOOD AND CLEAN CONTAINER | P64: Pickup : 2026-09-08, Return : 2026-09-08 ** PLEASE CHECK OPEN GATE BEFORE RETURN CONTAINER ** | Q64: 0 | R64: 0 | S64: 1 | T64: 0 | U64: 0 | V64: 0 | W64: 0 | X64: 0 | Y64: 0 | Z64: 0 | AA64: 0 | AB64: =SUM(Q64:Y64)-Z64 -> 1 | AC64: =IF(I64="","",IF(OR(LEFT(I64,3)="BKK",I64="LCH55"),"BKK",IF(LEFT(I64,3)="LCH","LCH","OTHER"))) -> LCH | AD64: =MAX(0,Q64-MAX(0,Z64-0)) -> 0 | AE64: =MAX(0,R64-MAX(0,Z64-SUM(Q64:Q64))) -> 0 | AF64: =MAX(0,S64-MAX(0,Z64-SUM(Q64:R64))) -> 1 | AG64: =MAX(0,T64-MAX(0,Z64-SUM(Q64:S64))) -> 0 | AH64: =MAX(0,U64-MAX(0,Z64-SUM(Q64:T64))) -> 0 | AI64: =MAX(0,V64-MAX(0,Z64-SUM(Q64:U64))) -> 0 | AJ64: =MAX(0,W64-MAX(0,Z64-SUM(Q64:V64))) -> 0 | AK64: =MAX(0,X64-MAX(0,Z64-SUM(Q64:W64))) -> 0 | AL64: =MAX(0,Y64-MAX(0,Z64-SUM(Q64:X64))) -> 0
A65: HASLS22260802563 | B65: SWCP | C65: 2609N | D65: 202609121200 | F65: THLCH | G65: KRINC | H65: 40Hx1 | I65: LCH27 | J65: HAST Logistics Co.,Ltd. | K65: 20260908 | L65: KORCHINA FREIGHT (THAILAND) CO., LTD. | M65: BRIDGESTONE AIRCRAFT TIRE MANUFACTURING (THAILAND) CO., LTD. | N65: EVAPORATOR | O65: GOOD AND CLEAN CONTAINER | P65: Pickup : 2026-09-08, Return : 2026-09-08 **CHECK OPENGATE BEFORE RETURN CNTR** | Q65: 0 | R65: 0 | S65: 1 | T65: 0 | U65: 0 | V65: 0 | W65: 0 | X65: 0 | Y65: 0 | Z65: 0 | AA65: 0 | AB65: =SUM(Q65:Y65)-Z65 -> 1 | AC65: =IF(I65="","",IF(OR(LEFT(I65,3)="BKK",I65="LCH55"),"BKK",IF(LEFT(I65,3)="LCH","LCH","OTHER"))) -> LCH | AD65: =MAX(0,Q65-MAX(0,Z65-0)) -> 0 | AE65: =MAX(0,R65-MAX(0,Z65-SUM(Q65:Q65))) -> 0 | AF65: =MAX(0,S65-MAX(0,Z65-SUM(Q65:R65))) -> 1 | AG65: =MAX(0,T65-MAX(0,Z65-SUM(Q65:S65))) -> 0 | AH65: =MAX(0,U65-MAX(0,Z65-SUM(Q65:T65))) -> 0 | AI65: =MAX(0,V65-MAX(0,Z65-SUM(Q65:U65))) -> 0 | AJ65: =MAX(0,W65-MAX(0,Z65-SUM(Q65:V65))) -> 0 | AK65: =MAX(0,X65-MAX(0,Z65-SUM(Q65:W65))) -> 0 | AL65: =MAX(0,Y65-MAX(0,Z65-SUM(Q65:X65))) -> 0
A66: HASLS22260700701 | B66: ICVY | C66: 2607S | D66: 202609191300 | F66: THLCH | G66: IDJKT | H66: 40Hx1 | I66: LCH27 | J66: HAST Logistics Co.,Ltd. | K66: 20260822 | L66: L.A.1 CO.,LTD. | M66: TANATEX CHEMICALS (THAILAND) CO., LTD. | N66: CHEMICALS PRODUCT (NON DG) | O66: REQUEST : CONTAINER MAX GROSS 32.50 TONS | P66: Pickup : 2026-08-22, Return : 2026-08-23 | Q66: 0 | R66: 0 | S66: 1 | T66: 0 | U66: 0 | V66: 0 | W66: 0 | X66: 0 | Y66: 0 | Z66: 0 | AA66: 0 | AB66: =SUM(Q66:Y66)-Z66 -> 1 | AC66: =IF(I66="","",IF(OR(LEFT(I66,3)="BKK",I66="LCH55"),"BKK",IF(LEFT(I66,3)="LCH","LCH","OTHER"))) -> LCH | AD66: =MAX(0,Q66-MAX(0,Z66-0)) -> 0 | AE66: =MAX(0,R66-MAX(0,Z66-SUM(Q66:Q66))) -> 0 | AF66: =MAX(0,S66-MAX(0,Z66-SUM(Q66:R66))) -> 1 | AG66: =MAX(0,T66-MAX(0,Z66-SUM(Q66:S66))) -> 0 | AH66: =MAX(0,U66-MAX(0,Z66-SUM(Q66:T66))) -> 0 | AI66: =MAX(0,V66-MAX(0,Z66-SUM(Q66:U66))) -> 0 | AJ66: =MAX(0,W66-MAX(0,Z66-SUM(Q66:V66))) -> 0 | AK66: =MAX(0,X66-MAX(0,Z66-SUM(Q66:W66))) -> 0 | AL66: =MAX(0,Y66-MAX(0,Z66-SUM(Q66:X66))) -> 0
A67: HASLS22260900253 | B67: SWCP | C67: 2609N | D67: 202609121200 | F67: THLCH | G67: VNSGN | H67: 40Hx1 | I67: LCHY5 | J67: PW DEPOT CO., LTD. | K67: 20260908 | L67: IRPC PUBLIC COMPANY LIMITED | M67: IRPC PUBLIC COMPANY LIMITED | N67: RESIN | O67: GOOD AND CLEAN CTNR | P67: CY-RTN 08-10/09/26 | Q67: 0 | R67: 0 | S67: 1 | T67: 0 | U67: 0 | V67: 0 | W67: 0 | X67: 0 | Y67: 0 | Z67: 0 | AA67: 0 | AB67: =SUM(Q67:Y67)-Z67 -> 1 | AC67: =IF(I67="","",IF(OR(LEFT(I67,3)="BKK",I67="LCH55"),"BKK",IF(LEFT(I67,3)="LCH","LCH","OTHER"))) -> LCH | AD67: =MAX(0,Q67-MAX(0,Z67-0)) -> 0 | AE67: =MAX(0,R67-MAX(0,Z67-SUM(Q67:Q67))) -> 0 | AF67: =MAX(0,S67-MAX(0,Z67-SUM(Q67:R67))) -> 1 | AG67: =MAX(0,T67-MAX(0,Z67-SUM(Q67:S67))) -> 0 | AH67: =MAX(0,U67-MAX(0,Z67-SUM(Q67:T67))) -> 0 | AI67: =MAX(0,V67-MAX(0,Z67-SUM(Q67:U67))) -> 0 | AJ67: =MAX(0,W67-MAX(0,Z67-SUM(Q67:V67))) -> 0 | AK67: =MAX(0,X67-MAX(0,Z67-SUM(Q67:W67))) -> 0 | AL67: =MAX(0,Y67-MAX(0,Z67-SUM(Q67:X67))) -> 0
A68: HASLS22260700882 | B68: SWSR | C68: 2610N | D68: 202609170300 | F68: THBKK | G68: KRPUS | H68: 40Hx1 20'x1 | I68: BKK01 | J68: PAT TERMINAL 2 (PORT AUTHORITY OF THAILAND) | K68: 20260827 | L68: GATEWAY CONTAINER LINE CO., LTD. | M68: GATEWAY CONTAINER LINE CO., LTD. | N68: GENERAL CARGO (CONSOL) | O68: CONSOLE | P68: Pickup : 2026-08-27, Return : 2026-08-28 CONSOLE | Q68: 1 | R68: 0 | S68: 1 | T68: 0 | U68: 0 | V68: 0 | W68: 0 | X68: 0 | Y68: 0 | Z68: 0 | AA68: 0 | AB68: =SUM(Q68:Y68)-Z68 -> 2 | AC68: =IF(I68="","",IF(OR(LEFT(I68,3)="BKK",I68="LCH55"),"BKK",IF(LEFT(I68,3)="LCH","LCH","OTHER"))) -> BKK | AD68: =MAX(0,Q68-MAX(0,Z68-0)) -> 1 | AE68: =MAX(0,R68-MAX(0,Z68-SUM(Q68:Q68))) -> 0 | AF68: =MAX(0,S68-MAX(0,Z68-SUM(Q68:R68))) -> 1 | AG68: =MAX(0,T68-MAX(0,Z68-SUM(Q68:S68))) -> 0 | AH68: =MAX(0,U68-MAX(0,Z68-SUM(Q68:T68))) -> 0 | AI68: =MAX(0,V68-MAX(0,Z68-SUM(Q68:U68))) -> 0 | AJ68: =MAX(0,W68-MAX(0,Z68-SUM(Q68:V68))) -> 0 | AK68: =MAX(0,X68-MAX(0,Z68-SUM(Q68:W68))) -> 0 | AL68: =MAX(0,Y68-MAX(0,Z68-SUM(Q68:X68))) -> 0
... A89: HASLS22260801873 | B89: YSVY | C89: 2607N | D89: 202609150200 | F89: THLCH | G89: JPTMK | H89: R40Hx1 | I89: LCH27 | J89: HAST Logistics Co.,Ltd. | K89: 20260907 | L89: LOGMAN INTERNATIONAL CO., LTD. | M89: THAI NIPPON FOODS CO. , LTD. | N89: FROZEN CHICKEN | O89: (Temp -20.0℃ / Vent Close) REQ: NEW AND CLEAN CONTAINER | P89: [FIX]Pickup : 2026-09-07, Return : 2026-09-10 (Temp -20.0 / Vent Close) CLS TIME 11/09/26 @18.0 | Q89: 0 | R89: 0 | S89: 0 | T89: 0 | U89: 1 | V89: 0 | W89: 0 | X89: 0 | Y89: 0 | Z89: 0 | AA89: 0 | AB89: =SUM(Q89:Y89)-Z89 -> 1 | AC89: =IF(I89="","",IF(OR(LEFT(I89,3)="BKK",I89="LCH55"),"BKK",IF(LEFT(I89,3)="LCH","LCH","OTHER"))) -> LCH | AD89: =MAX(0,Q89-MAX(0,Z89-0)) -> 0 | AE89: =MAX(0,R89-MAX(0,Z89-SUM(Q89:Q89))) -> 0 | AF89: =MAX(0,S89-MAX(0,Z89-SUM(Q89:R89))) -> 0 | AG89: =MAX(0,T89-MAX(0,Z89-SUM(Q89:S89))) -> 0 | AH89: =MAX(0,U89-MAX(0,Z89-SUM(Q89:T89))) -> 1 | AI89: =MAX(0,V89-MAX(0,Z89-SUM(Q89:U89))) -> 0 | AJ89: =MAX(0,W89-MAX(0,Z89-SUM(Q89:V89))) -> 0 | AK89: =MAX(0,X89-MAX(0,Z89-SUM(Q89:W89))) -> 0 | AL89: =MAX(0,Y89-MAX(0,Z89-SUM(Q89:X89))) -> 0
...

Sheet Balance Summary
A1: Remaining Balance by BK No — 98PD
A2: Balance = SUM(GP22,GP42,GP45,RE22,RE45,UT22,UT42,PC22,PC42) - Pickup (latest). Rows with Balance <= 0 are excluded from every sheet. The Pickup quantity is also deducted across the individual GP22...PC42 columns (in that order) to show remaining balance per container type. Rows with no Pickup Name are highlighted and need verification.
A4: BK No | B4: VSL | C4: VOY | D4: Pickup | E4: Pickup Name | F4: TPSZ | G4: Booked Qty | H4: Pickup Qty | I4: Balance (Return) | J4: GP22 Remaining | K4: GP42 Remaining | L4: GP45 Remaining | M4: RE22 Remaining | N4: RE45 Remaining | O4: UT22 Remaining | P4: UT42 Remaining | Q4: PC22 Remaining | R4: PC42 Remaining
A5: =Data!A51 -> HASLS22260900416 | B5: =Data!B51 -> SWBT | C5: =Data!C51 -> 2615N | D5: =Data!I51 -> 0 | E5: =Data!J51 -> 0 | F5: =Data!H51 -> 40Hx1 | G5: =SUM(Data!Q51:Y51) -> 1 | H5: =Data!Z51 -> 0 | I5: =G5-H5 -> 1 | J5: =Data!AD51 -> 0 | K5: =Data!AE51 -> 0 | L5: =Data!AF51 -> 1 | M5: =Data!AG51 -> 0 | N5: =Data!AH51 -> 0 | O5: =Data!AI51 -> 0 | P5: =Data!AJ51 -> 0 | Q5: =Data!AK51 -> 0 | R5: =Data!AL51 -> 0
A6: =Data!A50 -> HASLS22260701999 | B6: =Data!B50 -> SWSR | C6: =Data!C50 -> 2610N | D6: =Data!I50 -> BKK27 | E6: =Data!J50 -> B.C. DEPOT CO.,LTD. ( Bang-Na KM.18) | F6: =Data!H50 -> 20'x3 | G6: =SUM(Data!Q50:Y50) -> 3 | H6: =Data!Z50 -> 0 | I6: =G6-H6 -> 3 | J6: =Data!AD50 -> 3 | K6: =Data!AE50 -> 0 | L6: =Data!AF50 -> 0 | M6: =Data!AG50 -> 0 | N6: =Data!AH50 -> 0 | O6: =Data!AI50 -> 0 | P6: =Data!AJ50 -> 0 | Q6: =Data!AK50 -> 0 | R6: =Data!AL50 -> 0
A7: =Data!A49 -> HASLS22260800103 | B7: =Data!B49 -> SWIC | C7: =Data!C49 -> 2610N | D7: =Data!I49 -> BKK27 | E7: =Data!J49 -> B.C. DEPOT CO.,LTD. ( Bang-Na KM.18) | F7: =Data!H49 -> 20'x2 | G7: =SUM(Data!Q49:Y49) -> 2 | H7: =Data!Z49 -> 0 | I7: =G7-H7 -> 2 | J7: =Data!AD49 -> 2 | K7: =Data!AE49 -> 0 | L7: =Data!AF49 -> 0 | M7: =Data!AG49 -> 0 | N7: =Data!AH49 -> 0 | O7: =Data!AI49 -> 0 | P7: =Data!AJ49 -> 0 | Q7: =Data!AK49 -> 0 | R7: =Data!AL49 -> 0
A8: =Data!A53 -> HASLS22260801132 | B8: =Data!B53 -> SWMM | C8: =Data!C53 -> 2609N | D8: =Data!I53 -> BKK27 | E8: =Data!J53 -> B.C. DEPOT CO.,LTD. ( Bang-Na KM.18) | F8: =Data!H53 -> 40Hx1 | G8: =SUM(Data!Q53:Y53) -> 1 | H8: =Data!Z53 -> 0 | I8: =G8-H8 -> 1 | J8: =Data!AD53 -> 0 | K8: =Data!AE53 -> 0 | L8: =Data!AF53 -> 1 | M8: =Data!AG53 -> 0 | N8: =Data!AH53 -> 0 | O8: =Data!AI53 -> 0 | P8: =Data!AJ53 -> 0 | Q8: =Data!AK53 -> 0 | R8: =Data!AL53 -> 0
A9: =Data!A77 -> HASLS22260801246 | B9: =Data!B77 -> SWCP | C9: =Data!C77 -> 2609N | D9: =Data!I77 -> BKK27 | E9: =Data!J77 -> B.C. DEPOT CO.,LTD. ( Bang-Na KM.18) | F9: =Data!H77 -> 40Hx4 | G9: =SUM(Data!Q77:Y77) -> 4 | H9: =Data!Z77 -> 2 | I9: =G9-H9 -> 2 | J9: =Data!AD77 -> 0 | K9: =Data!AE77 -> 0 | L9: =Data!AF77 -> 2 | M9: =Data!AG77 -> 0 | N9: =Data!AH77 -> 0 | O9: =Data!AI77 -> 0 | P9: =Data!AJ77 -> 0 | Q9: =Data!AK77 -> 0 | R9: =Data!AL77 -> 0
A10: =Data!A44 -> HASLS22260801433 | B10: =Data!B44 -> NSSJ | C10: =Data!C44 -> 2607S | D10: =Data!I44 -> BKK27 | E10: =Data!J44 -> B.C. DEPOT CO.,LTD. ( Bang-Na KM.18) | F10: =Data!H44 -> 20'x2 | G10: =SUM(Data!Q44:Y44) -> 2 | H10: =Data!Z44 -> 0 | I10: =G10-H10 -> 2 | J10: =Data!AD44 -> 2 | K10: =Data!AE44 -> 0 | L10: =Data!AF44 -> 0 | M10: =Data!AG44 -> 0 | N10: =Data!AH44 -> 0 | O10: =Data!AI44 -> 0 | P10: =Data!AJ44 -> 0 | Q10: =Data!AK44 -> 0 | R10: =Data!AL44 -> 0
A11: =Data!A42 -> HASLS22260801444 | B11: =Data!B42 -> SWCP | C11: =Data!C42 -> 2609N | D11: =Data!I42 -> BKK27 | E11: =Data!J42 -> B.C. DEPOT CO.,LTD. ( Bang-Na KM.18) | F11: =Data!H42 -> 20'x10 | G11: =SUM(Data!Q42:Y42) -> 10 | H11: =Data!Z42 -> 0 | I11: =G11-H11 -> 10 | J11: =Data!AD42 -> 10 | K11: =Data!AE42 -> 0 | L11: =Data!AF42 -> 0 | M11: =Data!AG42 -> 0 | N11: =Data!AH42 -> 0 | O11: =Data!AI42 -> 0 | P11: =Data!AJ42 -> 0 | Q11: =Data!AK42 -> 0 | R11: =Data!AL42 -> 0
A12: =Data!A34 -> HASLS22260801612 | B12: =Data!B34 -> CMA | C12: =Data!C34 -> 2614N | D12: =Data!I34 -> BKK27 | E12: =Data!J34 -> B.C. DEPOT CO.,LTD. ( Bang-Na KM.18) | F12: =Data!H34 -> 20'x1 | G12: =SUM(Data!Q34:Y34) -> 1 | H12: =Data!Z34 -> 0 | I12: =G12-H12 -> 1 | J12: =Data!AD34 -> 1 | K12: =Data!AE34 -> 0 | L12: =Data!AF34 -> 0 | M12: =Data!AG34 -> 0 | N12: =Data!AH34 -> 0 | O12: =Data!AI34 -> 0 | P12: =Data!AJ34 -> 0 | Q12: =Data!AK34 -> 0 | R12: =Data!AL34 -> 0
A13: =Data!A39 -> HASLS22260801620 | B13: =Data!B39 -> SWSR | C13: =Data!C39 -> 2610N | D13: =Data!I39 -> BKK27 | E13: =Data!J39 -> B.C. DEPOT CO.,LTD. ( Bang-Na KM.18) | F13: =Data!H39 -> 20'x1 | G13: =SUM(Data!Q39:Y39) -> 1 | H13: =Data!Z39 -> 0 | I13: =G13-H13 -> 1 | J13: =Data!AD39 -> 1 | K13: =Data!AE39 -> 0 | L13: =Data!AF39 -> 0 | M13: =Data!AG39 -> 0 | N13: =Data!AH39 -> 0 | O13: =Data!AI39 -> 0 | P13: =Data!AJ39 -> 0 | Q13: =Data!AK39 -> 0 | R13: =Data!AL39 -> 0
A14: =Data!A46 -> HASLS22260801621 | B14: =Data!B46 -> SWSR | C14: =Data!C46 -> 2610N | D14: =Data!I46 -> BKK27 | E14: =Data!J46 -> B.C. DEPOT CO.,LTD. ( Bang-Na KM.18) | F14: =Data!H46 -> 20'x2 | G14: =SUM(Data!Q46:Y46) -> 2 | H14: =Data!Z46 -> 0 | I14: =G14-H14 -> 2 | J14: =Data!AD46 -> 2 | K14: =Data!AE46 -> 0 | L14: =Data!AF46 -> 0 | M14: =Data!AG46 -> 0 | N14: =Data!AH46 -> 0 | O14: =Data!AI46 -> 0 | P14: =Data!AJ46 -> 0 | Q14: =Data!AK46 -> 0 | R14: =Data!AL46 -> 0
A15: =Data!A33 -> HASLS22260801623 | B15: =Data!B33 -> SWSR | C15: =Data!C33 -> 2610N | D15: =Data!I33 -> BKK27 | E15: =Data!J33 -> B.C. DEPOT CO.,LTD. ( Bang-Na KM.18) | F15: =Data!H33 -> 20'x1 | G15: =SUM(Data!Q33:Y33) -> 1 | H15: =Data!Z33 -> 0 | I15: =G15-H15 -> 1 | J15: =Data!AD33 -> 1 | K15: =Data!AE33 -> 0 | L15: =Data!AF33 -> 0 | M15: =Data!AG33 -> 0 | N15: =Data!AH33 -> 0 | O15: =Data!AI33 -> 0 | P15: =Data!AJ33 -> 0 | Q15: =Data!AK33 -> 0 | R15: =Data!AL33 -> 0
A16: =Data!A9 -> HASLS22260801624 | B16: =Data!B9 -> SWSR | C16: =Data!C9 -> 2610N | D16: =Data!I9 -> BKK27 | E16: =Data!J9 -> B.C. DEPOT CO.,LTD. ( Bang-Na KM.18) | F16: =Data!H9 -> 20'x1 | G16: =SUM(Data!Q9:Y9) -> 1 | H16: =Data!Z9 -> 0 | I16: =G16-H16 -> 1 | J16: =Data!AD9 -> 1 | K16: =Data!AE9 -> 0 | L16: =Data!AF9 -> 0 | M16: =Data!AG9 -> 0 | N16: =Data!AH9 -> 0 | O16: =Data!AI9 -> 0 | P16: =Data!AJ9 -> 0 | Q16: =Data!AK9 -> 0 | R16: =Data!AL9 -> 0
A17: =Data!A29 -> HASLS22260801625 | B17: =Data!B29 -> SWSR | C17: =Data!C29 -> 2610N | D17: =Data!I29 -> BKK27 | E17: =Data!J29 -> B.C. DEPOT CO.,LTD. ( Bang-Na KM.18) | F17: =Data!H29 -> 20'x1 | G17: =SUM(Data!Q29:Y29) -> 1 | H17: =Data!Z29 -> 0 | I17: =G17-H17 -> 1 | J17: =Data!AD29 -> 1 | K17: =Data!AE29 -> 0 | L17: =Data!AF29 -> 0 | M17: =Data!AG29 -> 0 | N17: =Data!AH29 -> 0 | O17: =Data!AI29 -> 0 | P17: =Data!AJ29 -> 0 | Q17: =Data!AK29 -> 0 | R17: =Data!AL29 -> 0
A18: =Data!A28 -> HASLS22260801739 | B18: =Data!B28 -> SWSR | C18: =Data!C28 -> 2610N | D18: =Data!I28 -> BKK27 | E18: =Data!J28 -> B.C. DEPOT CO.,LTD. ( Bang-Na KM.18) | F18: =Data!H28 -> 20'x1 | G18: =SUM(Data!Q28:Y28) -> 1 | H18: =Data!Z28 -> 0 | I18: =G18-H18 -> 1 | J18: =Data!AD28 -> 1 | K18: =Data!AE28 -> 0 | L18: =Data!AF28 -> 0 | M18: =Data!AG28 -> 0 | N18: =Data!AH28 -> 0 | O18: =Data!AI28 -> 0 | P18: =Data!AJ28 -> 0 | Q18: =Data!AK28 -> 0 | R18: =Data!AL28 -> 0
A19: =Data!A2 -> HASLS22260801752 | B19: =Data!B2 -> SWSR | C19: =Data!C2 -> 2610N | D19: =Data!I2 -> BKK27 | E19: =Data!J2 -> B.C. DEPOT CO.,LTD. ( Bang-Na KM.18) | F19: =Data!H2 -> 20'x1 | G19: =SUM(Data!Q2:Y2) -> 1 | H19: =Data!Z2 -> 0 | I19: =G19-H19 -> 1 | J19: =Data!AD2 -> 1 | K19: =Data!AE2 -> 0 | L19: =Data!AF2 -> 0 | M19: =Data!AG2 -> 0 | N19: =Data!AH2 -> 0 | O19: =Data!AI2 -> 0 | P19: =Data!AJ2 -> 0 | Q19: =Data!AK2 -> 0 | R19: =Data!AL2 -> 0
A20: =Data!A70 -> HASLS22260801841 | B20: =Data!B70 -> SWBT | C20: =Data!C70 -> 2615N | D20: =Data!I70 -> BKK27 | E20: =Data!J70 -> B.C. DEPOT CO.,LTD. ( Bang-Na KM.18) | F20: =Data!H70 -> 40Hx17 | G20: =SUM(Data!Q70:Y70) -> 17 | H20: =Data!Z70 -> 9 | I20: =G20-H20 -> 8 | J20: =Data!AD70 -> 0 | K20: =Data!AE70 -> 0 | L20: =Data!AF70 -> 8 | M20: =Data!AG70 -> 0 | N20: =Data!AH70 -> 0 | O20: =Data!AI70 -> 0 | P20: =Data!AJ70 -> 0 | Q20: =Data!AK70 -> 0 | R20: =Data!AL70 -> 0
A21: =Data!A63 -> HASLS22260801939 | B21: =Data!B63 -> SWBT | C21: =Data!C63 -> 2615N | D21: =Data!I63 -> BKK27 | E21: =Data!J63 -> B.C. DEPOT CO.,LTD. ( Bang-Na KM.18) | F21: =Data!H63 -> 40Hx1 | G21: =SUM(Data!Q63:Y63) -> 1 | H21: =Data!Z63 -> 0 | I21: =G21-H21 -> 1 | J21: =Data!AD63 -> 0 | K21: =Data!AE63 -> 0 | L21: =Data!AF63 -> 1 | M21: =Data!AG63 -> 0 | N21: =Data!AH63 -> 0 | O21: =Data!AI63 -> 0 | P21: =Data!AJ63 -> 0 | Q21: =Data!AK63 -> 0 | R21: =Data!AL63 -> 0
A22: =Data!A55 -> HASLS22260802380 | B22: =Data!B55 -> KUS | C22: =Data!C55 -> 2615N | D22: =Data!I55 -> BKK27 | E22: =Data!J55 -> B.C. DEPOT CO.,LTD. ( Bang-Na KM.18) | F22: =Data!H55 -> 40Hx1 | G22: =SUM(Data!Q55:Y55) -> 1 | H22: =Data!Z55 -> 0 | I22: =G22-H22 -> 1 | J22: =Data!AD55 -> 0 | K22: =Data!AE55 -> 0 | L22: =Data!AF55 -> 1 | M22: =Data!AG55 -> 0 | N22: =Data!AH55 -> 0 | O22: =Data!AI55 -> 0 | P22: =Data!AJ55 -> 0 | Q22: =Data!AK55 -> 0 | R22: =Data!AL55 -> 0
A23: =Data!A3 -> HASLS22260802441 | B23: =Data!B3 -> SWSR | C23: =Data!C3 -> 2610N | D23: =Data!I3 -> BKK27 | E23: =Data!J3 -> B.C. DEPOT CO.,LTD. ( Bang-Na KM.18) | F23: =Data!H3 -> 20'x1 | G23: =SUM(Data!Q3:Y3) -> 1 | H23: =Data!Z3 -> 0 | I23: =G23-H23 -> 1 | J23: =Data!AD3 -> 1 | K23: =Data!AE3 -> 0 | L23: =Data!AF3 -> 0 | M23: =Data!AG3 -> 0 | N23: =Data!AH3 -> 0 | O23: =Data!AI3 -> 0 | P23: =Data!AJ3 -> 0 | Q23: =Data!AK3 -> 0 | R23: =Data!AL3 -> 0
A24: =Data!A80 -> HASLS22260900475 | B24: =Data!B80 -> DJCF | C24: =Data!C80 -> 0151N | D24: =Data!I80 -> BKK27 | E24: =Data!J80 -> B.C. DEPOT CO.,LTD. ( Bang-Na KM.18) | F24: =Data!H80 -> 40Hx5 | G24: =SUM(Data!Q80:Y80) -> 5 | H24: =Data!Z80 -> 0 | I24: =G24-H24 -> 5 | J24: =Data!AD80 -> 0 | K24: =Data!AE80 -> 0 | L24: =Data!AF80 -> 5 | M24: =Data!AG80 -> 0 | N24: =Data!AH80 -> 0 | O24: =Data!AI80 -> 0 | P24: =Data!AJ80 -> 0 | Q24: =Data!AK80 -> 0 | R24: =Data!AL80 -> 0
A25: =Data!A71 -> HASLS22260900486 | B25: =Data!B71 -> KJT | C25: =Data!C71 -> 2610N | D25: =Data!I71 -> BKK27 | E25: =Data!J71 -> B.C. DEPOT CO.,LTD. ( Bang-Na KM.18) | F25: =Data!H71 -> 40Hx2 | G25: =SUM(Data!Q71:Y71) -> 2 | H25: =Data!Z71 -> 0 | I25: =G25-H25 -> 2 | J25: =Data!AD71 -> 0 | K25: =Data!AE71 -> 0 | L25: =Data!AF71 -> 2 | M25: =Data!AG71 -> 0 | N25: =Data!AH71 -> 0 | O25: =Data!AI71 -> 0 | P25: =Data!AJ71 -> 0 | Q25: =Data!AK71 -> 0 | R25: =Data!AL71 -> 0
A26: =Data!A62 -> HASLS22260900696 | B26: =Data!B62 -> SWAL | C26: =Data!C62 -> 2608N | D26: =Data!I62 -> BKK27 | E26: =Data!J62 -> B.C. DEPOT CO.,LTD. ( Bang-Na KM.18) | F26: =Data!H62 -> 40Hx1 | G26: =SUM(Data!Q62:Y62) -> 1 | H26: =Data!Z62 -> 0 | I26: =G26-H26 -> 1 | J26: =Data!AD62 -> 0 | K26: =Data!AE62 -> 0 | L26: =Data!AF62 -> 1 | M26: =Data!AG62 -> 0 | N26: =Data!AH62 -> 0 | O26: =Data!AI62 -> 0 | P26: =Data!AJ62 -> 0 | Q26: =Data!AK62 -> 0 | R26: =Data!AL62 -> 0
A27: =Data!A60 -> HASLS22260801889 | B27: =Data!B60 -> ICVY | C27: =Data!C60 -> 2607S | D27: =Data!I60 -> LCH28 | E27: =Data!J60 -> CELLO | F27: =Data!H60 -> 40Hx1 | G27: =SUM(Data!Q60:Y60) -> 1 | H27: =Data!Z60 -> 0 | I27: =G27-H27 -> 1 | J27: =Data!AD60 -> 0 | K27: =Data!AE60 -> 0 | L27: =Data!AF60 -> 1 | M27: =Data!AG60 -> 0 | N27: =Data!AH60 -> 0 | O27: =Data!AI60 -> 0 | P27: =Data!AJ60 -> 0 | Q27: =Data!AK60 -> 0 | R27: =Data!AL60 -> 0
A28: =Data!A66 -> HASLS22260700701 | B28: =Data!B66 -> ICVY | C28: =Data!C66 -> 2607S | D28: =Data!I66 -> LCH27 | E28: =Data!J66 -> HAST Logistics Co.,Ltd. | F28: =Data!H66 -> 40Hx1 | G28: =SUM(Data!Q66:Y66) -> 1 | H28: =Data!Z66 -> 0 | I28: =G28-H28 -> 1 | J28: =Data!AD66 -> 0 | K28: =Data!AE66 -> 0 | L28: =Data!AF66 -> 1 | M28: =Data!AG66 -> 0 | N28: =Data!AH66 -> 0 | O28: =Data!AI66 -> 0 | P28: =Data!AJ66 -> 0 | Q28: =Data!AK66 -> 0 | R28: =Data!AL66 -> 0
A29: =Data!A61 -> HASLS22260800573 | B29: =Data!B61 -> DJCF | C29: =Data!C61 -> 0151N | D29: =Data!I61 -> LCH27 | E29: =Data!J61 -> HAST Logistics Co.,Ltd. | F29: =Data!H61 -> 40Hx1 | G29: =SUM(Data!Q61:Y61) -> 1 | H29: =Data!Z61 -> 0 | I29: =G29-H29 -> 1 | J29: =Data!AD61 -> 0 | K29: =Data!AE61 -> 0 | L29: =Data!AF61 -> 1 | M29: =Data!AG61 -> 0 | N29: =Data!AH61 -> 0 | O29: =Data!AI61 -> 0 | P29: =Data!AJ61 -> 0 | Q29: =Data!AK61 -> 0 | R29: =Data!AL61 -> 0
A30: =Data!A79 -> HASLS22260800855 | B30: =Data!B79 -> DJCF | C30: =Data!C79 -> 0151N | D30: =Data!I79 -> LCH27 | E30: =Data!J79 -> HAST Logistics Co.,Ltd. | F30: =Data!H79 -> 40Hx5 | G30: =SUM(Data!Q79:Y79) -> 5 | H30: =Data!Z79 -> 0 | I30: =G30-H30 -> 5 | J30: =Data!AD79 -> 0 | K30: =Data!AE79 -> 0 | L30: =Data!AF79 -> 5 | M30: =Data!AG79 -> 0 | N30: =Data!AH79 -> 0 | O30: =Data!AI79 -> 0 | P30: =Data!AJ79 -> 0 | Q30: =Data!AK79 -> 0 | R30: =Data!AL79 -> 0
A31: =Data!A19 -> HASLS22260801481 | B31: =Data!B19 -> NSSJ | C31: =Data!C19 -> 2607S | D31: =Data!I19 -> LCH27 | E31: =Data!J19 -> HAST Logistics Co.,Ltd. | F31: =Data!H19 -> 20'x1 | G31: =SUM(Data!Q19:Y19) -> 1 | H31: =Data!Z19 -> 0 | I31: =G31-H31 -> 1 | J31: =Data!AD19 -> 1 | K31: =Data!AE19 -> 0 | L31: =Data!AF19 -> 0 | M31: =Data!AG19 -> 0 | N31: =Data!AH19 -> 0 | O31: =Data!AI19 -> 0 | P31: =Data!AJ19 -> 0 | Q31: =Data!AK19 -> 0 | R31: =Data!AL19 -> 0
A32: =Data!A84 -> HASLS22260801673 | B32: =Data!B84 -> KJT | C32: =Data!C84 -> 2610N | D32: =Data!I84 -> LCH27 | E32: =Data!J84 -> HAST Logistics Co.,Ltd. | F32: =Data!H84 -> R40Hx1 | G32: =SUM(Data!Q84:Y84) -> 1 | H32: =Data!Z84 -> 0 | I32: =G32-H32 -> 1 | J32: =Data!AD84 -> 0 | K32: =Data!AE84 -> 0 | L32: =Data!AF84 -> 0 | M32: =Data!AG84 -> 0 | N32: =Data!AH84 -> 1 | O32: =Data!AI84 -> 0 | P32: =Data!AJ84 -> 0 | Q32: =Data!AK84 -> 0 | R32: =Data!AL84 -> 0
A33: =Data!A83 -> HASLS22260801674 | B33: =Data!B83 -> KJT | C33: =Data!C83 -> 2610N | D33: =Data!I83 -> LCH27 | E33: =Data!J83 -> HAST Logistics Co.,Ltd. | F33: =Data!H83 -> R40Hx1 | G33: =SUM(Data!Q83:Y83) -> 1 | H33: =Data!Z83 -> 0 | I33: =G33-H33 -> 1 | J33: =Data!AD83 -> 0 | K33: =Data!AE83 -> 0 | L33: =Data!AF83 -> 0 | M33: =Data!AG83 -> 0 | N33: =Data!AH83 -> 1 | O33: =Data!AI83 -> 0 | P33: =Data!AJ83 -> 0 | Q33: =Data!AK83 -> 0 | R33: =Data!AL83 -> 0
A34: =Data!A88 -> HASLS22260801675 | B34: =Data!B88 -> KJT | C34: =Data!C88 -> 2610N | D34: =Data!I88 -> LCH27 | E34: =Data!J88 -> HAST Logistics Co.,Ltd. | F34: =Data!H88 -> R40Hx1 | G34: =SUM(Data!Q88:Y88) -> 1 | H34: =Data!Z88 -> 0 | I34: =G34-H34 -> 1 | J34: =Data!AD88 -> 0 | K34: =Data!AE88 -> 0 | L34: =Data!AF88 -> 0 | M34: =Data!AG88 -> 0 | N34: =Data!AH88 -> 1 | O34: =Data!AI88 -> 0 | P34: =Data!AJ88 -> 0 | Q34: =Data!AK88 -> 0 | R34: =Data!AL88 -> 0
A35: =Data!A87 -> HASLS22260801677 | B35: =Data!B87 -> CMA | C35: =Data!C87 -> 2614N | D35: =Data!I87 -> LCH27 | E35: =Data!J87 -> HAST Logistics Co.,Ltd. | F35: =Data!H87 -> R40Hx1 | G35: =SUM(Data!Q87:Y87) -> 1 | H35: =Data!Z87 -> 0 | I35: =G35-H35 -> 1 | J35: =Data!AD87 -> 0 | K35: =Data!AE87 -> 0 | L35: =Data!AF87 -> 0 | M35: =Data!AG87 -> 0 | N35: =Data!AH87 -> 1 | O35: =Data!AI87 -> 0 | P35: =Data!AJ87 -> 0 | Q35: =Data!AK87 -> 0 | R35: =Data!AL87 -> 0
A36: =Data!A85 -> HASLS22260801679 | B36: =Data!B85 -> CMA | C36: =Data!C85 -> 2614N | D36: =Data!I85 -> LCH27 | E36: =Data!J85 -> HAST Logistics Co.,Ltd. | F36: =Data!H85 -> R40Hx1 | G36: =SUM(Data!Q85:Y85) -> 1 | H36: =Data!Z85 -> 0 | I36: =G36-H36 -> 1 | J36: =Data!AD85 -> 0 | K36: =Data!AE85 -> 0 | L36: =Data!AF85 -> 0 | M36: =Data!AG85 -> 0 | N36: =Data!AH85 -> 1 | O36: =Data!AI85 -> 0 | P36: =Data!AJ85 -> 0 | Q36: =Data!AK85 -> 0 | R36: =Data!AL85 -> 0
A37: =Data!A86 -> HASLS22260801681 | B37: =Data!B86 -> CMA | C37: =Data!C86 -> 2614N | D37: =Data!I86 -> LCH27 | E37: =Data!J86 -> HAST Logistics Co.,Ltd. | F37: =Data!H86 -> R40Hx1 | G37: =SUM(Data!Q86:Y86) -> 1 | H37: =Data!Z86 -> 0 | I37: =G37-H37 -> 1 | J37: =Data!AD86 -> 0 | K37: =Data!AE86 -> 0 | L37: =Data!AF86 -> 0 | M37: =Data!AG86 -> 0 | N37: =Data!AH86 -> 1 | O37: =Data!AI86 -> 0 | P37: =Data!AJ86 -> 0 | Q37: =Data!AK86 -> 0 | R37: =Data!AL86 -> 0
A38: =Data!A89 -> HASLS22260801873 | B38: =Data!B89 -> YSVY | C38: =Data!C89 -> 2607N | D38: =Data!I89 -> LCH27 | E38: =Data!J89 -> HAST Logistics Co.,Ltd. | F38: =Data!H89 -> R40Hx1 | G38: =SUM(Data!Q89:Y89) -> 1 | H38: =Data!Z89 -> 0 | I38: =G38-H38 -> 1 | J38: =Data!AD89 -> 0 | K38: =Data!AE89 -> 0 | L38: =Data!AF89 -> 0 | M38: =Data!AG89 -> 0 | N38: =Data!AH89 -> 1 | O38: =Data!AI89 -> 0 | P38: =Data!AJ89 -> 0 | Q38: =Data!AK89 -> 0 | R38: =Data!AL89 -> 0
A39: =Data!A21 -> HASLS22260802294 | B39: =Data!B21 -> YSVY | C39: =Data!C21 -> 2607N | D39: =Data!I21 -> LCH27 | E39: =Data!J21 -> HAST Logistics Co.,Ltd. | F39: =Data!H21 -> 20'x1 | G39: =SUM(Data!Q21:Y21) -> 1 | H39: =Data!Z21 -> 0 | I39: =G39-H39 -> 1 | J39: =Data!AD21 -> 1 | K39: =Data!AE21 -> 0 | L39: =Data!AF21 -> 0 | M39: =Data!AG21 -> 0 | N39: =Data!AH21 -> 0 | O39: =Data!AI21 -> 0 | P39: =Data!AJ21 -> 0 | Q39: =Data!AK21 -> 0 | R39: =Data!AL21 -> 0
A40: =Data!A27 -> HASLS22260802371 | B40: =Data!B27 -> YSVY | C40: =Data!C27 -> 2607N | D40: =Data!I27 -> LCH27 | E40: =Data!J27 -> HAST Logistics Co.,Ltd. | F40: =Data!H27 -> 20'x1 | G40: =SUM(Data!Q27:Y27) -> 1 | H40: =Data!Z27 -> 0 | I40: =G40-H40 -> 1 | J40: =Data!AD27 -> 1 | K40: =Data!AE27 -> 0 | L40: =Data!AF27 -> 0 | M40: =Data!AG27 -> 0 | N40: =Data!AH27 -> 0 | O40: =Data!AI27 -> 0 | P40: =Data!AJ27 -> 0 | Q40: =Data!AK27 -> 0 | R40: =Data!AL27 -> 0
A41: =Data!A81 -> HASLS22260802467 | B41: =Data!B81 -> DJCF | C41: =Data!C81 -> 0151N | D41: =Data!I81 -> LCH27 | E41: =Data!J81 -> HAST Logistics Co.,Ltd. | F41: =Data!H81 -> 40Hx7 | G41: =SUM(Data!Q81:Y81) -> 7 | H41: =Data!Z81 -> 0 | I41: =G41-H41 -> 7 | J41: =Data!AD81 -> 0 | K41: =Data!AE81 -> 0 | L41: =Data!AF81 -> 7 | M41: =Data!AG81 -> 0 | N41: =Data!AH81 -> 0 | O41: =Data!AI81 -> 0 | P41: =Data!AJ81 -> 0 | Q41: =Data!AK81 -> 0 | R41: =Data!AL81 -> 0
...

Sheet Summary
A1: 98PD — Outstanding Balance Summary by Pickup
A2: Container-type totals for BK Nos with a remaining balance (Balance > 0), grouped by Pickup. GP22...PC42 here are the NET remaining quantity per type (booked minus the Pickup already collected, allocated across types in order) — not the raw booked count. BKK01 and BKK04 are combined into one row; LCH55 is counted under the BKK group.
A4: Group | B4: Pickup | C4: Pickup Name | D4: Number of Records | E4: GP22 | F4: GP42 | G4: GP45 | H4: RE22 | I4: RE45 | J4: UT22 | K4: UT42 | L4: PC22 | M4: PC42 | N4: Total Containers
