Workbook

Sheet Data
A1: DATA — Outstanding bookings (Balance > 0) | source: 10-22-PD.xls
A2: BK No | B2: VSL | C2: VOY | D2: ETD | E2: POR | F2: LOD | G2: DIS | H2: TPSZ | I2: Pickup | J2: Pickup Name | K2: TRAN DT | L2: DOC CUST | M2: ORG CUST | N2: COMMODITY | O2: TRAFFIC ORDER | P2: COMMON REMARK | Q2: GP22 | R2: GP42 | S2: GP45 | T2: RE22 | U2: RE45 | V2: UT22 | W2: UT42 | X2: PC22 | Y2: PC42 | Z2: Pickup | AA2: Return | AB2: Balance (Booked - Pickup) | AC2: Group | AD2: GP22 Remaining | AE2: GP42 Remaining | AF2: GP45 Remaining | AG2: RE22 Remaining | AH2: RE45 Remaining | AI2: UT22 Remaining | AJ2: UT42 Remaining | AK2: PC22 Remaining | AL2: PC42 Remaining
A3: HASLS22260901678 | B3: HAHM | C3: 2612N | D3: 202610271500 | F3: THBKK | G3: JPKSM | H3: 20'x5 | I3: BKK27 | J3: B.C. DEPOT CO.,LTD. ( Bang-Na KM.18) | K3: 20261022 | L3: MEGALOAD DEVELOPMENT LOGISTICS CO., LTD. | M3: FISHMEAL MARKETING DEVELOPMENT CO., LTD. | N3: THAILAND STEAM DRIED FISHMEAL | O3: **APPROVED BY MJ CHANG DD.23/09/26** DG22GPx5 (CLS 9 / UN 2216) GOOD CONDITION OF CONTAINER, LOADING GOODS INTO CONTAINERD BY FOLKLIFT | P3: **APPROVED BY MJ CHANG DD.23/09/26** DG22GPx5 (CLS 9 / UN 2216) Pickup : 2026-10-22, Return : 2026-10-24 *CLS TIME 24/10/26 @23.59* | Q3: 5 | R3: 0 | S3: 0 | T3: 0 | U3: 0 | V3: 0 | W3: 0 | X3: 0 | Y3: 0 | Z3: 3 | AA3: 0 | AB3: =SUM(Q3:Y3)-Z3 | AC3: =IF(I3="","",IF(OR(LEFT(I3,3)="BKK",I3="LCH55"),"BKK",IF(LEFT(I3,3)="LCH","LCH","OTHER"))) | AD3: =MAX(0,Q3-MAX(0,Z3)) | AE3: =MAX(0,R3-MAX(0,Z3-SUM(Q3:Q3))) | AF3: =MAX(0,S3-MAX(0,Z3-SUM(Q3:R3))) | AG3: =MAX(0,T3-MAX(0,Z3-SUM(Q3:S3))) | AH3: =MAX(0,U3-MAX(0,Z3-SUM(Q3:T3))) | AI3: =MAX(0,V3-MAX(0,Z3-SUM(Q3:U3))) | AJ3: =MAX(0,W3-MAX(0,Z3-SUM(Q3:V3))) | AK3: =MAX(0,X3-MAX(0,Z3-SUM(Q3:W3))) | AL3: =MAX(0,Y3-MAX(0,Z3-SUM(Q3:X3)))
A4: HASLS22260901926 | B4: HAHM | C4: 2612N | D4: 202610271500 | F4: THBKK | G4: VNSGN | H4: 20'x20 | I4: BKK27 | J4: B.C. DEPOT CO.,LTD. ( Bang-Na KM.18) | K4: 20261021 | L4: SEA FLEXI LOGISTICS CO.,LTD. | M4: THANAKORN VEGETABLE OIL PRODUCTS CO., LTD. | N4: SOYBEAN OIL | O4: **APPROVED BY MJ CHANG DD.01/10/26***FLEXIBAG ONDECK* Survey : 2026-10-21, Pickup : 2026-10-22 REQUEST STRONG, CLEAN, FOOD GRADE CONTAINER | P4: **APPROVED BY MJ CHANG DD.01/10/26** *FLEXIBAG ONDECK* Survey : 2026-10-21, Pickup : 2026-10-22, Return : 2026-10-24 (EXTEND CLOSING 24/10/26 @23.59) | Q4: 20 | R4: 0 | S4: 0 | T4: 0 | U4: 0 | V4: 0 | W4: 0 | X4: 0 | Y4: 0 | Z4: 8 | AA4: 0 | AB4: =SUM(Q4:Y4)-Z4 | AC4: =IF(I4="","",IF(OR(LEFT(I4,3)="BKK",I4="LCH55"),"BKK",IF(LEFT(I4,3)="LCH","LCH","OTHER"))) | AD4: =MAX(0,Q4-MAX(0,Z4)) | AE4: =MAX(0,R4-MAX(0,Z4-SUM(Q4:Q4))) | AF4: =MAX(0,S4-MAX(0,Z4-SUM(Q4:R4))) | AG4: =MAX(0,T4-MAX(0,Z4-SUM(Q4:S4))) | AH4: =MAX(0,U4-MAX(0,Z4-SUM(Q4:T4))) | AI4: =MAX(0,V4-MAX(0,Z4-SUM(Q4:U4))) | AJ4: =MAX(0,W4-MAX(0,Z4-SUM(Q4:V4))) | AK4: =MAX(0,X4-MAX(0,Z4-SUM(Q4:W4))) | AL4: =MAX(0,Y4-MAX(0,Z4-SUM(Q4:X4)))
A5: HASLS22260902697 | B5: KMSU | C5: 2608S | D5: 202611012100 | E5: THLKR | F5: THLCH | G5: IDJKT | H5: 20'x1 | I5: BKK27 | J5: B.C. DEPOT CO.,LTD. ( Bang-Na KM.18) | K5: 20261020 | L5: LESCHACO (THAILAND) LTD. | M5: ORFFA (THAILAND) COMPANY LIMITED | N5: EXCENTIAL SELENIUM | O5: REQUEST CONTAINR GOOD AND CLEAN | P5: Pickup : 2026-10-20, Return : 2026-10-21 Paperless Code 2835 Closing Time LKB 2026-10-28 @ 23.59 | Q5: 1 | R5: 0 | S5: 0 | T5: 0 | U5: 0 | V5: 0 | W5: 0 | X5: 0 | Y5: 0 | Z5: 0 | AA5: 0 | AB5: =SUM(Q5:Y5)-Z5 | AC5: =IF(I5="","",IF(OR(LEFT(I5,3)="BKK",I5="LCH55"),"BKK",IF(LEFT(I5,3)="LCH","LCH","OTHER"))) | AD5: =MAX(0,Q5-MAX(0,Z5)) | AE5: =MAX(0,R5-MAX(0,Z5-SUM(Q5:Q5))) | AF5: =MAX(0,S5-MAX(0,Z5-SUM(Q5:R5))) | AG5: =MAX(0,T5-MAX(0,Z5-SUM(Q5:S5))) | AH5: =MAX(0,U5-MAX(0,Z5-SUM(Q5:T5))) | AI5: =MAX(0,V5-MAX(0,Z5-SUM(Q5:U5))) | AJ5: =MAX(0,W5-MAX(0,Z5-SUM(Q5:V5))) | AK5: =MAX(0,X5-MAX(0,Z5-SUM(Q5:W5))) | AL5: =MAX(0,Y5-MAX(0,Z5-SUM(Q5:X5)))
A6: HASLS22260902798 | B6: KMSU | C6: 2608S | D6: 202611012100 | E6: THLKR | F6: THLCH | G6: IDJKT | H6: 20'x1 | I6: BKK27 | J6: B.C. DEPOT CO.,LTD. ( Bang-Na KM.18) | K6: 20261020 | L6: LESCHACO (THAILAND) LTD. | M6: ORFFA (THAILAND) COMPANY LIMITED | N6: EXCENTIAL SELENIUM | O6: REQUEST CONTAINR GOOD AND CLEAN | P6: Pickup : 2026-10-20, Return : 2026-10-21 Paperless Code 2835 Closing Time LKB 2026-10-28 @ 23.59 | Q6: 1 | R6: 0 | S6: 0 | T6: 0 | U6: 0 | V6: 0 | W6: 0 | X6: 0 | Y6: 0 | Z6: 0 | AA6: 0 | AB6: =SUM(Q6:Y6)-Z6 | AC6: =IF(I6="","",IF(OR(LEFT(I6,3)="BKK",I6="LCH55"),"BKK",IF(LEFT(I6,3)="LCH","LCH","OTHER"))) | AD6: =MAX(0,Q6-MAX(0,Z6)) | AE6: =MAX(0,R6-MAX(0,Z6-SUM(Q6:Q6))) | AF6: =MAX(0,S6-MAX(0,Z6-SUM(Q6:R6))) | AG6: =MAX(0,T6-MAX(0,Z6-SUM(Q6:S6))) | AH6: =MAX(0,U6-MAX(0,Z6-SUM(Q6:T6))) | AI6: =MAX(0,V6-MAX(0,Z6-SUM(Q6:U6))) | AJ6: =MAX(0,W6-MAX(0,Z6-SUM(Q6:V6))) | AK6: =MAX(0,X6-MAX(0,Z6-SUM(Q6:W6))) | AL6: =MAX(0,Y6-MAX(0,Z6-SUM(Q6:X6)))
A7: HASLS22261000012 | B7: HAHM | C7: 2612N | D7: 202610271500 | F7: THBKK | G7: VNSGN | H7: 20'x5 | I7: BKK27 | J7: B.C. DEPOT CO.,LTD. ( Bang-Na KM.18) | K7: 20261021 | L7: ICONS GLOBAL LOGISTICS CO., LTD. | M7: ICONS GLOBAL LOGISTICS CO., LTD. | N7: SOYBEAN OIL | O7: ** APPROVED BY MJ CHANG DD.01/10/26** *FLEXIBAG ONDECK* Survey : 2026-10-21 | P7: ** APPROVED BY MJ CHANG DD.01/10/26** *FLEXIBAG ONDECK* SURVEY 21/10/2026 CY-RTN : 22*24/10/2026 | Q7: 5 | R7: 0 | S7: 0 | T7: 0 | U7: 0 | V7: 0 | W7: 0 | X7: 0 | Y7: 0 | Z7: 3 | AA7: 0 | AB7: =SUM(Q7:Y7)-Z7 | AC7: =IF(I7="","",IF(OR(LEFT(I7,3)="BKK",I7="LCH55"),"BKK",IF(LEFT(I7,3)="LCH","LCH","OTHER"))) | AD7: =MAX(0,Q7-MAX(0,Z7)) | AE7: =MAX(0,R7-MAX(0,Z7-SUM(Q7:Q7))) | AF7: =MAX(0,S7-MAX(0,Z7-SUM(Q7:R7))) | AG7: =MAX(0,T7-MAX(0,Z7-SUM(Q7:S7))) | AH7: =MAX(0,U7-MAX(0,Z7-SUM(Q7:T7))) | AI7: =MAX(0,V7-MAX(0,Z7-SUM(Q7:U7))) | AJ7: =MAX(0,W7-MAX(0,Z7-SUM(Q7:V7))) | AK7: =MAX(0,X7-MAX(0,Z7-SUM(Q7:W7))) | AL7: =MAX(0,Y7-MAX(0,Z7-SUM(Q7:X7)))
A8: HASLS22261000459 | B8: HAHM | C8: 2612N | D8: 202610271500 | F8: THBKK | G8: VNSGN | H8: 40Hx10 | I8: BKK27 | J8: B.C. DEPOT CO.,LTD. ( Bang-Na KM.18) | K8: 20261022 | L8: BIRLA CARBON (THAILAND) PUBLIC COMPANY LIMITED | M8: BIRLA CARBON (THAILAND) PUBLIC COMPANY LIMITED | N8: CABON BLACK | O8: **Clean container / No rust / No hole / No sharp surface inside areas in container. | P8: Pickup : 2026-10-22, Return : 2026-10-23 | Q8: 0 | R8: 0 | S8: 10 | T8: 0 | U8: 0 | V8: 0 | W8: 0 | X8: 0 | Y8: 0 | Z8: 2 | AA8: 0 | AB8: =SUM(Q8:Y8)-Z8 | AC8: =IF(I8="","",IF(OR(LEFT(I8,3)="BKK",I8="LCH55"),"BKK",IF(LEFT(I8,3)="LCH","LCH","OTHER"))) | AD8: =MAX(0,Q8-MAX(0,Z8)) | AE8: =MAX(0,R8-MAX(0,Z8-SUM(Q8:Q8))) | AF8: =MAX(0,S8-MAX(0,Z8-SUM(Q8:R8))) | AG8: =MAX(0,T8-MAX(0,Z8-SUM(Q8:S8))) | AH8: =MAX(0,U8-MAX(0,Z8-SUM(Q8:T8))) | AI8: =MAX(0,V8-MAX(0,Z8-SUM(Q8:U8))) | AJ8: =MAX(0,W8-MAX(0,Z8-SUM(Q8:V8))) | AK8: =MAX(0,X8-MAX(0,Z8-SUM(Q8:W8))) | AL8: =MAX(0,Y8-MAX(0,Z8-SUM(Q8:X8)))
A9: HASLS22261000623 | B9: SWIC | C9: 2612N | D9: 202611100000 | F9: THBKK | G9: JPTHS | H9: 40Hx1 | I9: BKK27 | J9: B.C. DEPOT CO.,LTD. ( Bang-Na KM.18) | K9: 20261016 | L9: UNIQUE INTERNATIONAL FORWARDING CO., LTD. | M9: BIRLA CARBON (THAILAND) PUBLIC COMPANY LIMITED | N9: CARBON BLACK (NON DG) | O9: CLEAN CONTAINER GRADE A | P9: [FIX]Pickup : 2026-10-16, Return : 2026-10-17 | Q9: 0 | R9: 0 | S9: 1 | T9: 0 | U9: 0 | V9: 0 | W9: 0 | X9: 0 | Y9: 0 | Z9: 0 | AA9: 0 | AB9: =SUM(Q9:Y9)-Z9 | AC9: =IF(I9="","",IF(OR(LEFT(I9,3)="BKK",I9="LCH55"),"BKK",IF(LEFT(I9,3)="LCH","LCH","OTHER"))) | AD9: =MAX(0,Q9-MAX(0,Z9)) | AE9: =MAX(0,R9-MAX(0,Z9-SUM(Q9:Q9))) | AF9: =MAX(0,S9-MAX(0,Z9-SUM(Q9:R9))) | AG9: =MAX(0,T9-MAX(0,Z9-SUM(Q9:S9))) | AH9: =MAX(0,U9-MAX(0,Z9-SUM(Q9:T9))) | AI9: =MAX(0,V9-MAX(0,Z9-SUM(Q9:U9))) | AJ9: =MAX(0,W9-MAX(0,Z9-SUM(Q9:V9))) | AK9: =MAX(0,X9-MAX(0,Z9-SUM(Q9:W9))) | AL9: =MAX(0,Y9-MAX(0,Z9-SUM(Q9:X9)))
A10: HASLS22261001582 | B10: KMBK | C10: 2613N | D10: 202611160000 | F10: THBKK | G10: VNSGN | H10: 20'x1 | I10: BKK27 | J10: B.C. DEPOT CO.,LTD. ( Bang-Na KM.18) | K10: 20261012 | L10: ALLIANZ GLOBAL LOGISTICS CO.,LTD. | M10: BANPONG TAPIOCA FLOUR INDUSTRIAL CO., LTD. | N10: FOOD FLOUR | O10: GOOD AND CLEAN CONTAINER | P10: Pickup : 2026-10-12, Return : 2026-10-13 | Q10: 1 | R10: 0 | S10: 0 | T10: 0 | U10: 0 | V10: 0 | W10: 0 | X10: 0 | Y10: 0 | Z10: 0 | AA10: 0 | AB10: =SUM(Q10:Y10)-Z10 | AC10: =IF(I10="","",IF(OR(LEFT(I10,3)="BKK",I10="LCH55"),"BKK",IF(LEFT(I10,3)="LCH","LCH","OTHER"))) | AD10: =MAX(0,Q10-MAX(0,Z10)) | AE10: =MAX(0,R10-MAX(0,Z10-SUM(Q10:Q10))) | AF10: =MAX(0,S10-MAX(0,Z10-SUM(Q10:R10))) | AG10: =MAX(0,T10-MAX(0,Z10-SUM(Q10:S10))) | AH10: =MAX(0,U10-MAX(0,Z10-SUM(Q10:T10))) | AI10: =MAX(0,V10-MAX(0,Z10-SUM(Q10:U10))) | AJ10: =MAX(0,W10-MAX(0,Z10-SUM(Q10:V10))) | AK10: =MAX(0,X10-MAX(0,Z10-SUM(Q10:W10))) | AL10: =MAX(0,Y10-MAX(0,Z10-SUM(Q10:X10)))
A11: HASLS22261001584 | B11: DJCF | C11: 0154N | D11: 202611240300 | F11: THBKK | G11: VNSGN | H11: 20'x1 | I11: BKK27 | J11: B.C. DEPOT CO.,LTD. ( Bang-Na KM.18) | K11: 20261020 | L11: ALLIANZ GLOBAL LOGISTICS CO.,LTD. | M11: BANPONG TAPIOCA FLOUR INDUSTRIAL CO., LTD. | N11: FOOD FLOUR | O11: GOOD AND CLEAN CONTAINER | P11: Pickup : 2026-10-20, Return : 2026-10-21 | Q11: 1 | R11: 0 | S11: 0 | T11: 0 | U11: 0 | V11: 0 | W11: 0 | X11: 0 | Y11: 0 | Z11: 0 | AA11: 0 | AB11: =SUM(Q11:Y11)-Z11 | AC11: =IF(I11="","",IF(OR(LEFT(I11,3)="BKK",I11="LCH55"),"BKK",IF(LEFT(I11,3)="LCH","LCH","OTHER"))) | AD11: =MAX(0,Q11-MAX(0,Z11)) | AE11: =MAX(0,R11-MAX(0,Z11-SUM(Q11:Q11))) | AF11: =MAX(0,S11-MAX(0,Z11-SUM(Q11:R11))) | AG11: =MAX(0,T11-MAX(0,Z11-SUM(Q11:S11))) | AH11: =MAX(0,U11-MAX(0,Z11-SUM(Q11:T11))) | AI11: =MAX(0,V11-MAX(0,Z11-SUM(Q11:U11))) | AJ11: =MAX(0,W11-MAX(0,Z11-SUM(Q11:V11))) | AK11: =MAX(0,X11-MAX(0,Z11-SUM(Q11:W11))) | AL11: =MAX(0,Y11-MAX(0,Z11-SUM(Q11:X11)))
A12: HASLS22260900467 | B12: SWSP | C12: 2610N | D12: 202611082100 | F12: THLCH | G12: VNSGN | H12: 40Hx6 | I12: LCH28 | J12: CELLO | K12: 20261022 | L12: WHA GC LOGISTICS COMPANY LIMITED | M12: PTT GLOBAL CHEMICAL PUBLIC COMPANY LIMITED | N12: RESIN | O12: GOOD AND CLEAN CTNR | P12: CY-RTN 22-27/10/26 [1ST RTN 27/10/2026 W/O RENT] ** PLEASE CHECK OPEN GATE BEFORE RETURN CONTAINER ** | Q12: 0 | R12: 0 | S12: 6 | T12: 0 | U12: 0 | V12: 0 | W12: 0 | X12: 0 | Y12: 0 | Z12: 2 | AA12: 0 | AB12: =SUM(Q12:Y12)-Z12 | AC12: =IF(I12="","",IF(OR(LEFT(I12,3)="BKK",I12="LCH55"),"BKK",IF(LEFT(I12,3)="LCH","LCH","OTHER"))) | AD12: =MAX(0,Q12-MAX(0,Z12)) | AE12: =MAX(0,R12-MAX(0,Z12-SUM(Q12:Q12))) | AF12: =MAX(0,S12-MAX(0,Z12-SUM(Q12:R12))) | AG12: =MAX(0,T12-MAX(0,Z12-SUM(Q12:S12))) | AH12: =MAX(0,U12-MAX(0,Z12-SUM(Q12:T12))) | AI12: =MAX(0,V12-MAX(0,Z12-SUM(Q12:U12))) | AJ12: =MAX(0,W12-MAX(0,Z12-SUM(Q12:V12))) | AK12: =MAX(0,X12-MAX(0,Z12-SUM(Q12:W12))) | AL12: =MAX(0,Y12-MAX(0,Z12-SUM(Q12:X12)))
A13: HASLS22261000016 | B13: SWSP | C13: 2610N | D13: 202611082100 | F13: THLCH | G13: VNSGN | H13: 40Hx4 | I13: LCH28 | J13: CELLO | K13: 20261021 | L13: WHA GC LOGISTICS COMPANY LIMITED | M13: PTT GLOBAL CHEMICAL PUBLIC COMPANY LIMITED | N13: RESIN | O13: GOOD AND CLEAN CTNR | P13: CY-RTN 21-24/10/26 (PR2610002025) *PLS CHECK OPEN GATE BEFORE RETURN CTNR* | Q13: 0 | R13: 0 | S13: 4 | T13: 0 | U13: 0 | V13: 0 | W13: 0 | X13: 0 | Y13: 0 | Z13: 0 | AA13: 0 | AB13: =SUM(Q13:Y13)-Z13 | AC13: =IF(I13="","",IF(OR(LEFT(I13,3)="BKK",I13="LCH55"),"BKK",IF(LEFT(I13,3)="LCH","LCH","OTHER"))) | AD13: =MAX(0,Q13-MAX(0,Z13)) | AE13: =MAX(0,R13-MAX(0,Z13-SUM(Q13:Q13))) | AF13: =MAX(0,S13-MAX(0,Z13-SUM(Q13:R13))) | AG13: =MAX(0,T13-MAX(0,Z13-SUM(Q13:S13))) | AH13: =MAX(0,U13-MAX(0,Z13-SUM(Q13:T13))) | AI13: =MAX(0,V13-MAX(0,Z13-SUM(Q13:U13))) | AJ13: =MAX(0,W13-MAX(0,Z13-SUM(Q13:V13))) | AK13: =MAX(0,X13-MAX(0,Z13-SUM(Q13:W13))) | AL13: =MAX(0,Y13-MAX(0,Z13-SUM(Q13:X13)))
A14: HASLS22261001160 | B14: SWSP | C14: 2610N | D14: 202611082100 | F14: THLCH | G14: VNSGN | H14: 20'x2 | I14: LCH28 | J14: CELLO | K14: 20261022 | L14: WHA GC LOGISTICS COMPANY LIMITED | M14: PTT GLOBAL CHEMICAL PUBLIC COMPANY LIMITED | N14: RESIN | O14: GOOD AND CLEAN CTNR | P14: CY-RTN 22-27/10/26 [1ST RTN 27/10/2026 W/O RENT] ** PLEASE CHECK OPEN GATE BEFORE RETURN CONTAINER ** | Q14: 2 | R14: 0 | S14: 0 | T14: 0 | U14: 0 | V14: 0 | W14: 0 | X14: 0 | Y14: 0 | Z14: 0 | AA14: 0 | AB14: =SUM(Q14:Y14)-Z14 | AC14: =IF(I14="","",IF(OR(LEFT(I14,3)="BKK",I14="LCH55"),"BKK",IF(LEFT(I14,3)="LCH","LCH","OTHER"))) | AD14: =MAX(0,Q14-MAX(0,Z14)) | AE14: =MAX(0,R14-MAX(0,Z14-SUM(Q14:Q14))) | AF14: =MAX(0,S14-MAX(0,Z14-SUM(Q14:R14))) | AG14: =MAX(0,T14-MAX(0,Z14-SUM(Q14:S14))) | AH14: =MAX(0,U14-MAX(0,Z14-SUM(Q14:T14))) | AI14: =MAX(0,V14-MAX(0,Z14-SUM(Q14:U14))) | AJ14: =MAX(0,W14-MAX(0,Z14-SUM(Q14:V14))) | AK14: =MAX(0,X14-MAX(0,Z14-SUM(Q14:W14))) | AL14: =MAX(0,Y14-MAX(0,Z14-SUM(Q14:X14)))
A15: HASLS22260900469 | B15: SWSP | C15: 2610N | D15: 202611082100 | F15: THLCH | G15: VNSGN | H15: 20'x5 | I15: LCH27 | J15: HAST Logistics Co.,Ltd. | K15: 20261022 | L15: WHA GC LOGISTICS COMPANY LIMITED | M15: PTT GLOBAL CHEMICAL PUBLIC COMPANY LIMITED | N15: RESIN | O15: GOOD AND CLEAN CTNR | P15: CY-RTN 22-27/10/26 [1ST RTN 27/10/2026 W/O RENT] (PR2610003950) ** PLEASE CHECK OPEN GATE BEFORE RETURN CONTAINER ** | Q15: 5 | R15: 0 | S15: 0 | T15: 0 | U15: 0 | V15: 0 | W15: 0 | X15: 0 | Y15: 0 | Z15: 0 | AA15: 0 | AB15: =SUM(Q15:Y15)-Z15 | AC15: =IF(I15="","",IF(OR(LEFT(I15,3)="BKK",I15="LCH55"),"BKK",IF(LEFT(I15,3)="LCH","LCH","OTHER"))) | AD15: =MAX(0,Q15-MAX(0,Z15)) | AE15: =MAX(0,R15-MAX(0,Z15-SUM(Q15:Q15))) | AF15: =MAX(0,S15-MAX(0,Z15-SUM(Q15:R15))) | AG15: =MAX(0,T15-MAX(0,Z15-SUM(Q15:S15))) | AH15: =MAX(0,U15-MAX(0,Z15-SUM(Q15:T15))) | AI15: =MAX(0,V15-MAX(0,Z15-SUM(Q15:U15))) | AJ15: =MAX(0,W15-MAX(0,Z15-SUM(Q15:V15))) | AK15: =MAX(0,X15-MAX(0,Z15-SUM(Q15:W15))) | AL15: =MAX(0,Y15-MAX(0,Z15-SUM(Q15:X15)))
A16: HASLS22260900470 | B16: DJCF | C16: 0153N | D16: 202611032200 | F16: THLCH | G16: VNSGN | H16: 20'x9 | I16: LCH27 | J16: HAST Logistics Co.,Ltd. | K16: 20261022 | L16: WHA GC LOGISTICS COMPANY LIMITED | M16: PTT GLOBAL CHEMICAL PUBLIC COMPANY LIMITED | N16: RESIN | O16: GOOD AND CLEAN CTNR | P16: CY-RTN 22-28/10/26 (PR2610003187) | Q16: 9 | R16: 0 | S16: 0 | T16: 0 | U16: 0 | V16: 0 | W16: 0 | X16: 0 | Y16: 0 | Z16: 0 | AA16: 0 | AB16: =SUM(Q16:Y16)-Z16 | AC16: =IF(I16="","",IF(OR(LEFT(I16,3)="BKK",I16="LCH55"),"BKK",IF(LEFT(I16,3)="LCH","LCH","OTHER"))) | AD16: =MAX(0,Q16-MAX(0,Z16)) | AE16: =MAX(0,R16-MAX(0,Z16-SUM(Q16:Q16))) | AF16: =MAX(0,S16-MAX(0,Z16-SUM(Q16:R16))) | AG16: =MAX(0,T16-MAX(0,Z16-SUM(Q16:S16))) | AH16: =MAX(0,U16-MAX(0,Z16-SUM(Q16:T16))) | AI16: =MAX(0,V16-MAX(0,Z16-SUM(Q16:U16))) | AJ16: =MAX(0,W16-MAX(0,Z16-SUM(Q16:V16))) | AK16: =MAX(0,X16-MAX(0,Z16-SUM(Q16:W16))) | AL16: =MAX(0,Y16-MAX(0,Z16-SUM(Q16:X16)))
A17: HASLS22260900471 | B17: KUS | C17: 2617N | D17: 202611070000 | F17: THLCH | G17: VNSGN | H17: 20'x20 | I17: LCH27 | J17: HAST Logistics Co.,Ltd. | K17: 20261022 | L17: WHA GC LOGISTICS COMPANY LIMITED | M17: PTT GLOBAL CHEMICAL PUBLIC COMPANY LIMITED | N17: RESIN | O17: GOOD AND CLEAN CTNR | P17: CY-RTN 22-30/10/26 | Q17: 20 | R17: 0 | S17: 0 | T17: 0 | U17: 0 | V17: 0 | W17: 0 | X17: 0 | Y17: 0 | Z17: 0 | AA17: 0 | AB17: =SUM(Q17:Y17)-Z17 | AC17: =IF(I17="","",IF(OR(LEFT(I17,3)="BKK",I17="LCH55"),"BKK",IF(LEFT(I17,3)="LCH","LCH","OTHER"))) | AD17: =MAX(0,Q17-MAX(0,Z17)) | AE17: =MAX(0,R17-MAX(0,Z17-SUM(Q17:Q17))) | AF17: =MAX(0,S17-MAX(0,Z17-SUM(Q17:R17))) | AG17: =MAX(0,T17-MAX(0,Z17-SUM(Q17:S17))) | AH17: =MAX(0,U17-MAX(0,Z17-SUM(Q17:T17))) | AI17: =MAX(0,V17-MAX(0,Z17-SUM(Q17:U17))) | AJ17: =MAX(0,W17-MAX(0,Z17-SUM(Q17:V17))) | AK17: =MAX(0,X17-MAX(0,Z17-SUM(Q17:W17))) | AL17: =MAX(0,Y17-MAX(0,Z17-SUM(Q17:X17)))
A18: HASLS22260901941 | B18: SWDN | C18: 2611N | D18: 202611020200 | F18: THLCH | G18: CNXMN | H18: R40Hx1 | I18: LCH27 | J18: HAST Logistics Co.,Ltd. | K18: 20261014 | L18: POSTMAN (THAILAND) CO.,LTD. | M18: POSTMAN (THAILAND) CO.,LTD. | N18: FRESH LONGAN | O18: RF45REx1 (Temp +2.0℃ / Vent 15% Open) | P18: Pickup : 2026-10-14, Return : 2026-10-22 (Temp +2.0℃ / Vent 15% Open) CLS TIME 24/10 @05.00 | Q18: 0 | R18: 0 | S18: 0 | T18: 0 | U18: 1 | V18: 0 | W18: 0 | X18: 0 | Y18: 0 | Z18: 0 | AA18: 0 | AB18: =SUM(Q18:Y18)-Z18 | AC18: =IF(I18="","",IF(OR(LEFT(I18,3)="BKK",I18="LCH55"),"BKK",IF(LEFT(I18,3)="LCH","LCH","OTHER"))) | AD18: =MAX(0,Q18-MAX(0,Z18)) | AE18: =MAX(0,R18-MAX(0,Z18-SUM(Q18:Q18))) | AF18: =MAX(0,S18-MAX(0,Z18-SUM(Q18:R18))) | AG18: =MAX(0,T18-MAX(0,Z18-SUM(Q18:S18))) | AH18: =MAX(0,U18-MAX(0,Z18-SUM(Q18:T18))) | AI18: =MAX(0,V18-MAX(0,Z18-SUM(Q18:U18))) | AJ18: =MAX(0,W18-MAX(0,Z18-SUM(Q18:V18))) | AK18: =MAX(0,X18-MAX(0,Z18-SUM(Q18:W18))) | AL18: =MAX(0,Y18-MAX(0,Z18-SUM(Q18:X18)))
... A53: HASLS22261001719 | B53: HAHM | C53: 2612N | D53: 202610271500 | F53: THBKK | G53: KRPUS | H53: 20'x1 | I53: BKK01 | J53: PAT TERMINAL 2 (PORT AUTHORITY OF THAILAND) | K53: 20261022 | L53: ECU WORLDWIDE (THAILAND) CO., LTD. | M53: ECU WORLDWIDE (THAILAND) CO., LTD. | N53: GENERAL CARGO (CONSOL) | O53: CONSOL | P53: Pickup : 2026-10-22, Return : 2026-10-22 CONSOL | Q53: 1 | R53: 0 | S53: 0 | T53: 0 | U53: 0 | V53: 0 | W53: 0 | X53: 0 | Y53: 0 | Z53: 0 | AA53: 0 | AB53: =SUM(Q53:Y53)-Z53 | AC53: =IF(I53="","",IF(OR(LEFT(I53,3)="BKK",I53="LCH55"),"BKK",IF(LEFT(I53,3)="LCH","LCH","OTHER"))) | AD53: =MAX(0,Q53-MAX(0,Z53)) | AE53: =MAX(0,R53-MAX(0,Z53-SUM(Q53:Q53))) | AF53: =MAX(0,S53-MAX(0,Z53-SUM(Q53:R53))) | AG53: =MAX(0,T53-MAX(0,Z53-SUM(Q53:S53))) | AH53: =MAX(0,U53-MAX(0,Z53-SUM(Q53:T53))) | AI53: =MAX(0,V53-MAX(0,Z53-SUM(Q53:U53))) | AJ53: =MAX(0,W53-MAX(0,Z53-SUM(Q53:V53))) | AK53: =MAX(0,X53-MAX(0,Z53-SUM(Q53:W53))) | AL53: =MAX(0,Y53-MAX(0,Z53-SUM(Q53:X53)))
A54: HASLS22260801848 | B54: TBN | C54: 001 | F54: THLCH | G54: JPYKK | H54: 20'x3 | I54: LCHY5 | J54: PW DEPOT CO., LTD. | K54: 20260908 | L54: DOW CHEMICAL THAILAND LTD. | M54: DOW CHEMICAL THAILAND LTD. | N54: RESIN | O54: RQST CNTR SEABULK & GRADE A | P54: CY CNTR DD.09/09/2026 RQST CNTR SEABULK & GRADE A | Q54: 3 | R54: 0 | S54: 0 | T54: 0 | U54: 0 | V54: 0 | W54: 0 | X54: 0 | Y54: 0 | Z54: 0 | AA54: 0 | AB54: =SUM(Q54:Y54)-Z54 | AC54: =IF(I54="","",IF(OR(LEFT(I54,3)="BKK",I54="LCH55"),"BKK",IF(LEFT(I54,3)="LCH","LCH","OTHER"))) | AD54: =MAX(0,Q54-MAX(0,Z54)) | AE54: =MAX(0,R54-MAX(0,Z54-SUM(Q54:Q54))) | AF54: =MAX(0,S54-MAX(0,Z54-SUM(Q54:R54))) | AG54: =MAX(0,T54-MAX(0,Z54-SUM(Q54:S54))) | AH54: =MAX(0,U54-MAX(0,Z54-SUM(Q54:T54))) | AI54: =MAX(0,V54-MAX(0,Z54-SUM(Q54:U54))) | AJ54: =MAX(0,W54-MAX(0,Z54-SUM(Q54:V54))) | AK54: =MAX(0,X54-MAX(0,Z54-SUM(Q54:W54))) | AL54: =MAX(0,Y54-MAX(0,Z54-SUM(Q54:X54)))
A55: HASLS22260900547 | B55: TBN | C55: 001 | F55: THLCH | G55: JPTRG | H55: 20'x3 | I55: LCHY5 | J55: PW DEPOT CO., LTD. | K55: 20260924 | L55: DOW CHEMICAL THAILAND LTD. | M55: DOW CHEMICAL THAILAND LTD. | N55: RESIN | O55: RQST CNTR SEABULK & GRADE A | P55: CY CNTR DD.24/09/2026 RQST CNTR SEABULK & GRADE A | Q55: 3 | R55: 0 | S55: 0 | T55: 0 | U55: 0 | V55: 0 | W55: 0 | X55: 0 | Y55: 0 | Z55: 0 | AA55: 0 | AB55: =SUM(Q55:Y55)-Z55 | AC55: =IF(I55="","",IF(OR(LEFT(I55,3)="BKK",I55="LCH55"),"BKK",IF(LEFT(I55,3)="LCH","LCH","OTHER"))) | AD55: =MAX(0,Q55-MAX(0,Z55)) | AE55: =MAX(0,R55-MAX(0,Z55-SUM(Q55:Q55))) | AF55: =MAX(0,S55-MAX(0,Z55-SUM(Q55:R55))) | AG55: =MAX(0,T55-MAX(0,Z55-SUM(Q55:S55))) | AH55: =MAX(0,U55-MAX(0,Z55-SUM(Q55:T55))) | AI55: =MAX(0,V55-MAX(0,Z55-SUM(Q55:U55))) | AJ55: =MAX(0,W55-MAX(0,Z55-SUM(Q55:V55))) | AK55: =MAX(0,X55-MAX(0,Z55-SUM(Q55:W55))) | AL55: =MAX(0,Y55-MAX(0,Z55-SUM(Q55:X55)))
A56: HASLS22260900548 | B56: TBN | C56: 001 | F56: THLCH | G56: JPTRG | H56: 20'x11 | I56: LCHY5 | J56: PW DEPOT CO., LTD. | K56: 20260925 | L56: DOW CHEMICAL THAILAND LTD. | M56: DOW CHEMICAL THAILAND LTD. | N56: RESIN | O56: RQST CNTR SEABULK & GRADE A | P56: CY CNTR DD.25/09/2026 RQST CNTR SEABULK & GRADE A | Q56: 11 | R56: 0 | S56: 0 | T56: 0 | U56: 0 | V56: 0 | W56: 0 | X56: 0 | Y56: 0 | Z56: 0 | AA56: 0 | AB56: =SUM(Q56:Y56)-Z56 | AC56: =IF(I56="","",IF(OR(LEFT(I56,3)="BKK",I56="LCH55"),"BKK",IF(LEFT(I56,3)="LCH","LCH","OTHER"))) | AD56: =MAX(0,Q56-MAX(0,Z56)) | AE56: =MAX(0,R56-MAX(0,Z56-SUM(Q56:Q56))) | AF56: =MAX(0,S56-MAX(0,Z56-SUM(Q56:R56))) | AG56: =MAX(0,T56-MAX(0,Z56-SUM(Q56:S56))) | AH56: =MAX(0,U56-MAX(0,Z56-SUM(Q56:T56))) | AI56: =MAX(0,V56-MAX(0,Z56-SUM(Q56:U56))) | AJ56: =MAX(0,W56-MAX(0,Z56-SUM(Q56:V56))) | AK56: =MAX(0,X56-MAX(0,Z56-SUM(Q56:W56))) | AL56: =MAX(0,Y56-MAX(0,Z56-SUM(Q56:X56)))
A57: HASLS22260900550 | B57: TBN | C57: 001 | F57: THLCH | G57: JPYKK | H57: 20'x9 | I57: LCHY5 | J57: PW DEPOT CO., LTD. | K57: 20260917 | L57: DOW CHEMICAL THAILAND LTD. | M57: DOW CHEMICAL THAILAND LTD. | N57: RESIN | O57: RQST CNTR SEABULK & GRADE A | P57: CY CNTR DD.17/09/2026 RQST CNTR SEABULK & GRADE A | Q57: 9 | R57: 0 | S57: 0 | T57: 0 | U57: 0 | V57: 0 | W57: 0 | X57: 0 | Y57: 0 | Z57: 5 | AA57: 0 | AB57: =SUM(Q57:Y57)-Z57 | AC57: =IF(I57="","",IF(OR(LEFT(I57,3)="BKK",I57="LCH55"),"BKK",IF(LEFT(I57,3)="LCH","LCH","OTHER"))) | AD57: =MAX(0,Q57-MAX(0,Z57)) | AE57: =MAX(0,R57-MAX(0,Z57-SUM(Q57:Q57))) | AF57: =MAX(0,S57-MAX(0,Z57-SUM(Q57:R57))) | AG57: =MAX(0,T57-MAX(0,Z57-SUM(Q57:S57))) | AH57: =MAX(0,U57-MAX(0,Z57-SUM(Q57:T57))) | AI57: =MAX(0,V57-MAX(0,Z57-SUM(Q57:U57))) | AJ57: =MAX(0,W57-MAX(0,Z57-SUM(Q57:V57))) | AK57: =MAX(0,X57-MAX(0,Z57-SUM(Q57:W57))) | AL57: =MAX(0,Y57-MAX(0,Z57-SUM(Q57:X57)))
A58: HASLS22260900551 | B58: TBN | C58: 001 | F58: THLCH | G58: JPYKK | H58: 20'x10 | I58: LCHY5 | J58: PW DEPOT CO., LTD. | K58: 20260926 | L58: DOW CHEMICAL THAILAND LTD. | M58: DOW CHEMICAL THAILAND LTD. | N58: RESIN | O58: RQST CNTR SEABULK & GRADE A | P58: CY CNTR DD.26/09/2026 RQST CNTR SEABULK & GRADE A | Q58: 10 | R58: 0 | S58: 0 | T58: 0 | U58: 0 | V58: 0 | W58: 0 | X58: 0 | Y58: 0 | Z58: 0 | AA58: 0 | AB58: =SUM(Q58:Y58)-Z58 | AC58: =IF(I58="","",IF(OR(LEFT(I58,3)="BKK",I58="LCH55"),"BKK",IF(LEFT(I58,3)="LCH","LCH","OTHER"))) | AD58: =MAX(0,Q58-MAX(0,Z58)) | AE58: =MAX(0,R58-MAX(0,Z58-SUM(Q58:Q58))) | AF58: =MAX(0,S58-MAX(0,Z58-SUM(Q58:R58))) | AG58: =MAX(0,T58-MAX(0,Z58-SUM(Q58:S58))) | AH58: =MAX(0,U58-MAX(0,Z58-SUM(Q58:T58))) | AI58: =MAX(0,V58-MAX(0,Z58-SUM(Q58:U58))) | AJ58: =MAX(0,W58-MAX(0,Z58-SUM(Q58:V58))) | AK58: =MAX(0,X58-MAX(0,Z58-SUM(Q58:W58))) | AL58: =MAX(0,Y58-MAX(0,Z58-SUM(Q58:X58)))
A59: HASLS22260901660 | B59: KXM | C59: 2609S | D59: 202611130200 | F59: THLCH | G59: IDJKT | H59: 40Hx3 | I59: LCHY5 | J59: PW DEPOT CO., LTD. | K59: 20261005 | L59: YUSEN LOGISTICS (THAILAND) CO., LTD. | M59: OATSIDE (THAILAND) LIMITED. | N59: OAT MILK ( GOOD GRADE CONTAINER REQUIRED) | O59: Good dry and clean container Food grade container only Rust-Free interior No Physical Damage. | P59: Pickup : 2026-10-05, Return : 2026-10-05 | Q59: 0 | R59: 0 | S59: 3 | T59: 0 | U59: 0 | V59: 0 | W59: 0 | X59: 0 | Y59: 0 | Z59: 0 | AA59: 0 | AB59: =SUM(Q59:Y59)-Z59 | AC59: =IF(I59="","",IF(OR(LEFT(I59,3)="BKK",I59="LCH55"),"BKK",IF(LEFT(I59,3)="LCH","LCH","OTHER"))) | AD59: =MAX(0,Q59-MAX(0,Z59)) | AE59: =MAX(0,R59-MAX(0,Z59-SUM(Q59:Q59))) | AF59: =MAX(0,S59-MAX(0,Z59-SUM(Q59:R59))) | AG59: =MAX(0,T59-MAX(0,Z59-SUM(Q59:S59))) | AH59: =MAX(0,U59-MAX(0,Z59-SUM(Q59:T59))) | AI59: =MAX(0,V59-MAX(0,Z59-SUM(Q59:U59))) | AJ59: =MAX(0,W59-MAX(0,Z59-SUM(Q59:V59))) | AK59: =MAX(0,X59-MAX(0,Z59-SUM(Q59:W59))) | AL59: =MAX(0,Y59-MAX(0,Z59-SUM(Q59:X59)))
A60: HASLS22260901815 | B60: SWAT | C60: 2611N | D60: 202611050900 | F60: THLCH | G60: JPOSA | H60: 20'x1 | I60: LCHY5 | J60: PW DEPOT CO., LTD. | K60: 20261021 | L60: CHEMICAL MATE SDN BHD | M60: GLOBAL GREEN CHEMICALS PUBLIC COMPANY LIMITED | N60: REFINED GLYCERINE 99.5% USP | O60: GOOD AND CLEAN CONTAINER | P60: Pickup : 2026-10-21, Return : 2026-10-23 | Q60: 1 | R60: 0 | S60: 0 | T60: 0 | U60: 0 | V60: 0 | W60: 0 | X60: 0 | Y60: 0 | Z60: 0 | AA60: 0 | AB60: =SUM(Q60:Y60)-Z60 | AC60: =IF(I60="","",IF(OR(LEFT(I60,3)="BKK",I60="LCH55"),"BKK",IF(LEFT(I60,3)="LCH","LCH","OTHER"))) | AD60: =MAX(0,Q60-MAX(0,Z60)) | AE60: =MAX(0,R60-MAX(0,Z60-SUM(Q60:Q60))) | AF60: =MAX(0,S60-MAX(0,Z60-SUM(Q60:R60))) | AG60: =MAX(0,T60-MAX(0,Z60-SUM(Q60:S60))) | AH60: =MAX(0,U60-MAX(0,Z60-SUM(Q60:T60))) | AI60: =MAX(0,V60-MAX(0,Z60-SUM(Q60:U60))) | AJ60: =MAX(0,W60-MAX(0,Z60-SUM(Q60:V60))) | AK60: =MAX(0,X60-MAX(0,Z60-SUM(Q60:W60))) | AL60: =MAX(0,Y60-MAX(0,Z60-SUM(Q60:X60)))
A61: HASLS22260901945 | B61: TBN | C61: 001 | F61: THLCH | G61: JPYKK | H61: 20'x7 | I61: LCHY5 | J61: PW DEPOT CO., LTD. | K61: 20260924 | L61: DOW CHEMICAL THAILAND LTD. | M61: DOW CHEMICAL THAILAND LTD. | N61: RESIN | O61: RQST CNTR SEABULK & GRADE A | P61: CY CNTR DD.24/09/2026 RQST CNTR SEABULK & GRADE A | Q61: 7 | R61: 0 | S61: 0 | T61: 0 | U61: 0 | V61: 0 | W61: 0 | X61: 0 | Y61: 0 | Z61: 6 | AA61: 0 | AB61: =SUM(Q61:Y61)-Z61 | AC61: =IF(I61="","",IF(OR(LEFT(I61,3)="BKK",I61="LCH55"),"BKK",IF(LEFT(I61,3)="LCH","LCH","OTHER"))) | AD61: =MAX(0,Q61-MAX(0,Z61)) | AE61: =MAX(0,R61-MAX(0,Z61-SUM(Q61:Q61))) | AF61: =MAX(0,S61-MAX(0,Z61-SUM(Q61:R61))) | AG61: =MAX(0,T61-MAX(0,Z61-SUM(Q61:S61))) | AH61: =MAX(0,U61-MAX(0,Z61-SUM(Q61:T61))) | AI61: =MAX(0,V61-MAX(0,Z61-SUM(Q61:U61))) | AJ61: =MAX(0,W61-MAX(0,Z61-SUM(Q61:V61))) | AK61: =MAX(0,X61-MAX(0,Z61-SUM(Q61:W61))) | AL61: =MAX(0,Y61-MAX(0,Z61-SUM(Q61:X61)))
A62: HASLS22260901946 | B62: TBN | C62: 001 | F62: THLCH | G62: JPYKK | H62: 20'x4 | I62: LCHY5 | J62: PW DEPOT CO., LTD. | K62: 20260925 | L62: DOW CHEMICAL THAILAND LTD. | M62: DOW CHEMICAL THAILAND LTD. | N62: RESIN | O62: RQST CNTR SEABULK & GRADE A | P62: CY CNTR DD.25/09/2026 RQST CNTR SEABULK & GRADE A | Q62: 4 | R62: 0 | S62: 0 | T62: 0 | U62: 0 | V62: 0 | W62: 0 | X62: 0 | Y62: 0 | Z62: 1 | AA62: 0 | AB62: =SUM(Q62:Y62)-Z62 | AC62: =IF(I62="","",IF(OR(LEFT(I62,3)="BKK",I62="LCH55"),"BKK",IF(LEFT(I62,3)="LCH","LCH","OTHER"))) | AD62: =MAX(0,Q62-MAX(0,Z62)) | AE62: =MAX(0,R62-MAX(0,Z62-SUM(Q62:Q62))) | AF62: =MAX(0,S62-MAX(0,Z62-SUM(Q62:R62))) | AG62: =MAX(0,T62-MAX(0,Z62-SUM(Q62:S62))) | AH62: =MAX(0,U62-MAX(0,Z62-SUM(Q62:T62))) | AI62: =MAX(0,V62-MAX(0,Z62-SUM(Q62:U62))) | AJ62: =MAX(0,W62-MAX(0,Z62-SUM(Q62:V62))) | AK62: =MAX(0,X62-MAX(0,Z62-SUM(Q62:W62))) | AL62: =MAX(0,Y62-MAX(0,Z62-SUM(Q62:X62)))
A63: HASLS22261000078 | B63: SWSP | C63: 2610N | D63: 202611082100 | F63: THLCH | G63: JPOSA | H63: 20'x1 | I63: LCHY5 | J63: PW DEPOT CO., LTD. | K63: 20261022 | L63: CHEMICAL MATE SDN BHD | M63: GLOBAL GREEN CHEMICALS PUBLIC COMPANY LIMITED | N63: REFINED GLYCERINE 99.5% USP | O63: GOOD AND CLEAN CONTAINER | P63: Pickup : 2026-10-22, Return : 2026-10-26 | Q63: 1 | R63: 0 | S63: 0 | T63: 0 | U63: 0 | V63: 0 | W63: 0 | X63: 0 | Y63: 0 | Z63: 0 | AA63: 0 | AB63: =SUM(Q63:Y63)-Z63 | AC63: =IF(I63="","",IF(OR(LEFT(I63,3)="BKK",I63="LCH55"),"BKK",IF(LEFT(I63,3)="LCH","LCH","OTHER"))) | AD63: =MAX(0,Q63-MAX(0,Z63)) | AE63: =MAX(0,R63-MAX(0,Z63-SUM(Q63:Q63))) | AF63: =MAX(0,S63-MAX(0,Z63-SUM(Q63:R63))) | AG63: =MAX(0,T63-MAX(0,Z63-SUM(Q63:S63))) | AH63: =MAX(0,U63-MAX(0,Z63-SUM(Q63:T63))) | AI63: =MAX(0,V63-MAX(0,Z63-SUM(Q63:U63))) | AJ63: =MAX(0,W63-MAX(0,Z63-SUM(Q63:V63))) | AK63: =MAX(0,X63-MAX(0,Z63-SUM(Q63:W63))) | AL63: =MAX(0,Y63-MAX(0,Z63-SUM(Q63:X63)))
A64: HASLS22261000172 | B64: HAB | C64: 2612N | D64: 202610290200 | F64: THLCH | G64: CNSHA | H64: 40Hx6 | I64: LCHY5 | J64: PW DEPOT CO., LTD. | K64: 20261016 | L64: WHA GC LOGISTICS COMPANY LIMITED | M64: PTT GLOBAL CHEMICAL PUBLIC COMPANY LIMITED | N64: RESIN | O64: GOOD AND CLEAN CONTAINER | P64: CY-RTN : 16-21/10/2026 | Q64: 0 | R64: 0 | S64: 6 | T64: 0 | U64: 0 | V64: 0 | W64: 0 | X64: 0 | Y64: 0 | Z64: 2 | AA64: 0 | AB64: =SUM(Q64:Y64)-Z64 | AC64: =IF(I64="","",IF(OR(LEFT(I64,3)="BKK",I64="LCH55"),"BKK",IF(LEFT(I64,3)="LCH","LCH","OTHER"))) | AD64: =MAX(0,Q64-MAX(0,Z64)) | AE64: =MAX(0,R64-MAX(0,Z64-SUM(Q64:Q64))) | AF64: =MAX(0,S64-MAX(0,Z64-SUM(Q64:R64))) | AG64: =MAX(0,T64-MAX(0,Z64-SUM(Q64:S64))) | AH64: =MAX(0,U64-MAX(0,Z64-SUM(Q64:T64))) | AI64: =MAX(0,V64-MAX(0,Z64-SUM(Q64:U64))) | AJ64: =MAX(0,W64-MAX(0,Z64-SUM(Q64:V64))) | AK64: =MAX(0,X64-MAX(0,Z64-SUM(Q64:W64))) | AL64: =MAX(0,Y64-MAX(0,Z64-SUM(Q64:X64)))
A65: HASLS22261000205 | B65: SWAT | C65: 2611N | D65: 202611050900 | F65: THLCH | G65: JPIYM | H65: 20'x5 | I65: LCHY5 | J65: PW DEPOT CO., LTD. | K65: 20261021 | L65: WHA GC LOGISTICS COMPANY LIMITED | M65: PTT GLOBAL CHEMICAL PUBLIC COMPANY LIMITED | N65: RESIN | O65: *** REQ. GOOD & CLEAN CONT. .( NO SMELL) *** | P65: CY-RTN 21-24/10/26 (PR2610003397) | Q65: 5 | R65: 0 | S65: 0 | T65: 0 | U65: 0 | V65: 0 | W65: 0 | X65: 0 | Y65: 0 | Z65: 2 | AA65: 0 | AB65: =SUM(Q65:Y65)-Z65 | AC65: =IF(I65="","",IF(OR(LEFT(I65,3)="BKK",I65="LCH55"),"BKK",IF(LEFT(I65,3)="LCH","LCH","OTHER"))) | AD65: =MAX(0,Q65-MAX(0,Z65)) | AE65: =MAX(0,R65-MAX(0,Z65-SUM(Q65:Q65))) | AF65: =MAX(0,S65-MAX(0,Z65-SUM(Q65:R65))) | AG65: =MAX(0,T65-MAX(0,Z65-SUM(Q65:S65))) | AH65: =MAX(0,U65-MAX(0,Z65-SUM(Q65:T65))) | AI65: =MAX(0,V65-MAX(0,Z65-SUM(Q65:U65))) | AJ65: =MAX(0,W65-MAX(0,Z65-SUM(Q65:V65))) | AK65: =MAX(0,X65-MAX(0,Z65-SUM(Q65:W65))) | AL65: =MAX(0,Y65-MAX(0,Z65-SUM(Q65:X65)))
A66: HASLS22261000303 | B66: SWDN | C66: 2611N | D66: 202611020200 | F66: THLCH | G66: KRINC | H66: 40Hx1 | I66: LCHY5 | J66: PW DEPOT CO., LTD. | K66: 20261022 | L66: CANVAS GLOBAL LOGISTICS (THAILAND) CO., LTD. | M66: SRI TRANG GLOVES (THAILAND) PUBLIC COMPANY LIMITED | N66: GLOVES | O66: GOOD AND CLEAN CONTAINER | P66: Pickup : 2026-10-22, Return : 2026-10-26 ** PLEASE CHECK OPEN GATE BEFORE RETURN CONTAINER ** | Q66: 0 | R66: 0 | S66: 1 | T66: 0 | U66: 0 | V66: 0 | W66: 0 | X66: 0 | Y66: 0 | Z66: 0 | AA66: 0 | AB66: =SUM(Q66:Y66)-Z66 | AC66: =IF(I66="","",IF(OR(LEFT(I66,3)="BKK",I66="LCH55"),"BKK",IF(LEFT(I66,3)="LCH","LCH","OTHER"))) | AD66: =MAX(0,Q66-MAX(0,Z66)) | AE66: =MAX(0,R66-MAX(0,Z66-SUM(Q66:Q66))) | AF66: =MAX(0,S66-MAX(0,Z66-SUM(Q66:R66))) | AG66: =MAX(0,T66-MAX(0,Z66-SUM(Q66:S66))) | AH66: =MAX(0,U66-MAX(0,Z66-SUM(Q66:T66))) | AI66: =MAX(0,V66-MAX(0,Z66-SUM(Q66:U66))) | AJ66: =MAX(0,W66-MAX(0,Z66-SUM(Q66:V66))) | AK66: =MAX(0,X66-MAX(0,Z66-SUM(Q66:W66))) | AL66: =MAX(0,Y66-MAX(0,Z66-SUM(Q66:X66)))
A67: HASLS22261000344 | B67: HMVY | C67: 2609N | D67: 202610271500 | F67: THLCH | G67: JPNGO | H67: 20'x1 | I67: LCHY5 | J67: PW DEPOT CO., LTD. | K67: 20261019 | L67: DOW CHEMICAL THAILAND LTD. | M67: SIAM POLYETHYLENE CO., LTD. | N67: RESIN | O67: 1X20' SEABULK | P67: Pickup : 2026-10-19, Return : 2026-10-22 ** PLEASE CHECK OPEN GATE BEFORE RETURN CONTAINER ** | Q67: 1 | R67: 0 | S67: 0 | T67: 0 | U67: 0 | V67: 0 | W67: 0 | X67: 0 | Y67: 0 | Z67: 0 | AA67: 0 | AB67: =SUM(Q67:Y67)-Z67 | AC67: =IF(I67="","",IF(OR(LEFT(I67,3)="BKK",I67="LCH55"),"BKK",IF(LEFT(I67,3)="LCH","LCH","OTHER"))) | AD67: =MAX(0,Q67-MAX(0,Z67)) | AE67: =MAX(0,R67-MAX(0,Z67-SUM(Q67:Q67))) | AF67: =MAX(0,S67-MAX(0,Z67-SUM(Q67:R67))) | AG67: =MAX(0,T67-MAX(0,Z67-SUM(Q67:S67))) | AH67: =MAX(0,U67-MAX(0,Z67-SUM(Q67:T67))) | AI67: =MAX(0,V67-MAX(0,Z67-SUM(Q67:U67))) | AJ67: =MAX(0,W67-MAX(0,Z67-SUM(Q67:V67))) | AK67: =MAX(0,X67-MAX(0,Z67-SUM(Q67:W67))) | AL67: =MAX(0,Y67-MAX(0,Z67-SUM(Q67:X67)))
A68: HASLS22261000345 | B68: HMVY | C68: 2609N | D68: 202610271500 | F68: THLCH | G68: JPNGO | H68: 20'x1 | I68: LCHY5 | J68: PW DEPOT CO., LTD. | K68: 20261019 | L68: DOW CHEMICAL THAILAND LTD. | M68: SIAM POLYETHYLENE CO., LTD. | N68: RESIN | O68: 1X20' SEABULK | P68: Pickup : 2026-10-19, Return : 2026-10-22 | Q68: 1 | R68: 0 | S68: 0 | T68: 0 | U68: 0 | V68: 0 | W68: 0 | X68: 0 | Y68: 0 | Z68: 0 | AA68: 0 | AB68: =SUM(Q68:Y68)-Z68 | AC68: =IF(I68="","",IF(OR(LEFT(I68,3)="BKK",I68="LCH55"),"BKK",IF(LEFT(I68,3)="LCH","LCH","OTHER"))) | AD68: =MAX(0,Q68-MAX(0,Z68)) | AE68: =MAX(0,R68-MAX(0,Z68-SUM(Q68:Q68))) | AF68: =MAX(0,S68-MAX(0,Z68-SUM(Q68:R68))) | AG68: =MAX(0,T68-MAX(0,Z68-SUM(Q68:S68))) | AH68: =MAX(0,U68-MAX(0,Z68-SUM(Q68:T68))) | AI68: =MAX(0,V68-MAX(0,Z68-SUM(Q68:U68))) | AJ68: =MAX(0,W68-MAX(0,Z68-SUM(Q68:V68))) | AK68: =MAX(0,X68-MAX(0,Z68-SUM(Q68:W68))) | AL68: =MAX(0,Y68-MAX(0,Z68-SUM(Q68:X68)))
A69: HASLS22261000347 | B69: HMVY | C69: 2609N | D69: 202610271500 | F69: THLCH | G69: JPNGO | H69: 20'x1 | I69: LCHY5 | J69: PW DEPOT CO., LTD. | K69: 20261019 | L69: DOW CHEMICAL THAILAND LTD. | M69: SIAM POLYETHYLENE CO., LTD. | N69: RESIN | O69: 1X20' SEABULK | P69: Pickup : 2026-10-19, Return : 2026-10-22 ** PLEASE CHECK OPEN GATE BEFORE RETURN CONTAINER ** | Q69: 1 | R69: 0 | S69: 0 | T69: 0 | U69: 0 | V69: 0 | W69: 0 | X69: 0 | Y69: 0 | Z69: 0 | AA69: 0 | AB69: =SUM(Q69:Y69)-Z69 | AC69: =IF(I69="","",IF(OR(LEFT(I69,3)="BKK",I69="LCH55"),"BKK",IF(LEFT(I69,3)="LCH","LCH","OTHER"))) | AD69: =MAX(0,Q69-MAX(0,Z69)) | AE69: =MAX(0,R69-MAX(0,Z69-SUM(Q69:Q69))) | AF69: =MAX(0,S69-MAX(0,Z69-SUM(Q69:R69))) | AG69: =MAX(0,T69-MAX(0,Z69-SUM(Q69:S69))) | AH69: =MAX(0,U69-MAX(0,Z69-SUM(Q69:T69))) | AI69: =MAX(0,V69-MAX(0,Z69-SUM(Q69:U69))) | AJ69: =MAX(0,W69-MAX(0,Z69-SUM(Q69:V69))) | AK69: =MAX(0,X69-MAX(0,Z69-SUM(Q69:W69))) | AL69: =MAX(0,Y69-MAX(0,Z69-SUM(Q69:X69)))
A70: HASLS22261000348 | B70: HAB | C70: 2612N | D70: 202610290200 | F70: THLCH | G70: JPYKK | H70: 20'x1 | I70: LCHY5 | J70: PW DEPOT CO., LTD. | K70: 20261019 | L70: DOW CHEMICAL THAILAND LTD. | M70: SIAM POLYETHYLENE CO., LTD. | N70: RESIN | O70: 1X20' SEABULK | P70: Pickup : 2026-10-19, Return : 2026-10-22 ** PLEASE CHECK OPEN GATE BEFORE RETURN CONTAINER ** | Q70: 1 | R70: 0 | S70: 0 | T70: 0 | U70: 0 | V70: 0 | W70: 0 | X70: 0 | Y70: 0 | Z70: 0 | AA70: 0 | AB70: =SUM(Q70:Y70)-Z70 | AC70: =IF(I70="","",IF(OR(LEFT(I70,3)="BKK",I70="LCH55"),"BKK",IF(LEFT(I70,3)="LCH","LCH","OTHER"))) | AD70: =MAX(0,Q70-MAX(0,Z70)) | AE70: =MAX(0,R70-MAX(0,Z70-SUM(Q70:Q70))) | AF70: =MAX(0,S70-MAX(0,Z70-SUM(Q70:R70))) | AG70: =MAX(0,T70-MAX(0,Z70-SUM(Q70:S70))) | AH70: =MAX(0,U70-MAX(0,Z70-SUM(Q70:T70))) | AI70: =MAX(0,V70-MAX(0,Z70-SUM(Q70:U70))) | AJ70: =MAX(0,W70-MAX(0,Z70-SUM(Q70:V70))) | AK70: =MAX(0,X70-MAX(0,Z70-SUM(Q70:W70))) | AL70: =MAX(0,Y70-MAX(0,Z70-SUM(Q70:X70)))
A71: HASLS22261000349 | B71: HAB | C71: 2612N | D71: 202610290200 | F71: THLCH | G71: JPYKK | H71: 20'x1 | I71: LCHY5 | J71: PW DEPOT CO., LTD. | K71: 20261019 | L71: DOW CHEMICAL THAILAND LTD. | M71: SIAM POLYETHYLENE CO., LTD. | N71: RESIN | O71: 1X20' SEABULK | P71: Pickup : 2026-10-19, Return : 2026-10-22 ** PLEASE CHECK OPEN GATE BEFORE RETURN CONTAINER ** | Q71: 1 | R71: 0 | S71: 0 | T71: 0 | U71: 0 | V71: 0 | W71: 0 | X71: 0 | Y71: 0 | Z71: 0 | AA71: 0 | AB71: =SUM(Q71:Y71)-Z71 | AC71: =IF(I71="","",IF(OR(LEFT(I71,3)="BKK",I71="LCH55"),"BKK",IF(LEFT(I71,3)="LCH","LCH","OTHER"))) | AD71: =MAX(0,Q71-MAX(0,Z71)) | AE71: =MAX(0,R71-MAX(0,Z71-SUM(Q71:Q71))) | AF71: =MAX(0,S71-MAX(0,Z71-SUM(Q71:R71))) | AG71: =MAX(0,T71-MAX(0,Z71-SUM(Q71:S71))) | AH71: =MAX(0,U71-MAX(0,Z71-SUM(Q71:T71))) | AI71: =MAX(0,V71-MAX(0,Z71-SUM(Q71:U71))) | AJ71: =MAX(0,W71-MAX(0,Z71-SUM(Q71:V71))) | AK71: =MAX(0,X71-MAX(0,Z71-SUM(Q71:W71))) | AL71: =MAX(0,Y71-MAX(0,Z71-SUM(Q71:X71)))
A72: HASLS22261000411 | B72: SWSP | C72: 2610N | D72: 202611082100 | F72: THLCH | G72: JPYKK | H72: 20'x1 | I72: LCHY5 | J72: PW DEPOT CO., LTD. | K72: 20261019 | L72: DOW CHEMICAL THAILAND LTD. | M72: SIAM POLYETHYLENE CO., LTD. | N72: RESIN | O72: 1X20' SEABULK | P72: Pickup : 2026-10-19, Return : 2026-10-22 (1ST RTN DD: 27/10/26 WO/RENT) **CHECK OPENGATE BEFORE RETURN CNTR** | Q72: 1 | R72: 0 | S72: 0 | T72: 0 | U72: 0 | V72: 0 | W72: 0 | X72: 0 | Y72: 0 | Z72: 0 | AA72: 0 | AB72: =SUM(Q72:Y72)-Z72 | AC72: =IF(I72="","",IF(OR(LEFT(I72,3)="BKK",I72="LCH55"),"BKK",IF(LEFT(I72,3)="LCH","LCH","OTHER"))) | AD72: =MAX(0,Q72-MAX(0,Z72)) | AE72: =MAX(0,R72-MAX(0,Z72-SUM(Q72:Q72))) | AF72: =MAX(0,S72-MAX(0,Z72-SUM(Q72:R72))) | AG72: =MAX(0,T72-MAX(0,Z72-SUM(Q72:S72))) | AH72: =MAX(0,U72-MAX(0,Z72-SUM(Q72:T72))) | AI72: =MAX(0,V72-MAX(0,Z72-SUM(Q72:U72))) | AJ72: =MAX(0,W72-MAX(0,Z72-SUM(Q72:V72))) | AK72: =MAX(0,X72-MAX(0,Z72-SUM(Q72:W72))) | AL72: =MAX(0,Y72-MAX(0,Z72-SUM(Q72:X72)))
A73: HASLS22261000414 | B73: SWSP | C73: 2610N | D73: 202611082100 | F73: THLCH | G73: JPYKK | H73: 20'x1 | I73: LCHY5 | J73: PW DEPOT CO., LTD. | K73: 20261019 | L73: DOW CHEMICAL THAILAND LTD. | M73: SIAM POLYETHYLENE CO., LTD. | N73: RESIN | O73: 1X20' SEABULK | P73: Pickup : 2026-10-19, Return : 2026-10-22 (1ST RTN DD: 27/10/26 WO/RENT) **CHECK OPENGATE BEFORE RETURN CNTR** | Q73: 1 | R73: 0 | S73: 0 | T73: 0 | U73: 0 | V73: 0 | W73: 0 | X73: 0 | Y73: 0 | Z73: 0 | AA73: 0 | AB73: =SUM(Q73:Y73)-Z73 | AC73: =IF(I73="","",IF(OR(LEFT(I73,3)="BKK",I73="LCH55"),"BKK",IF(LEFT(I73,3)="LCH","LCH","OTHER"))) | AD73: =MAX(0,Q73-MAX(0,Z73)) | AE73: =MAX(0,R73-MAX(0,Z73-SUM(Q73:Q73))) | AF73: =MAX(0,S73-MAX(0,Z73-SUM(Q73:R73))) | AG73: =MAX(0,T73-MAX(0,Z73-SUM(Q73:S73))) | AH73: =MAX(0,U73-MAX(0,Z73-SUM(Q73:T73))) | AI73: =MAX(0,V73-MAX(0,Z73-SUM(Q73:U73))) | AJ73: =MAX(0,W73-MAX(0,Z73-SUM(Q73:V73))) | AK73: =MAX(0,X73-MAX(0,Z73-SUM(Q73:W73))) | AL73: =MAX(0,Y73-MAX(0,Z73-SUM(Q73:X73)))
A74: HASLS22261000603 | B74: SWIC | C74: 2612N | D74: 202611101600 | F74: THLCH | G74: JPUKB | H74: 20'x7 | I74: LCHY5 | J74: PW DEPOT CO., LTD. | K74: 20261021 | L74: WHA GC LOGISTICS COMPANY LIMITED | M74: PTT GLOBAL CHEMICAL PUBLIC COMPANY LIMITED | N74: RESIN | O74: SEA BULK CTNR // SURVEY DD.21/10 | P74: SURVEY DD.21/10/2026 CY-RTN : 22-06/11/2026 (PR2610004294 ) *PLS CHECK OPEN GATE BEFORE RETURN CTNR* | Q74: 7 | R74: 0 | S74: 0 | T74: 0 | U74: 0 | V74: 0 | W74: 0 | X74: 0 | Y74: 0 | Z74: 0 | AA74: 0 | AB74: =SUM(Q74:Y74)-Z74 | AC74: =IF(I74="","",IF(OR(LEFT(I74,3)="BKK",I74="LCH55"),"BKK",IF(LEFT(I74,3)="LCH","LCH","OTHER"))) | AD74: =MAX(0,Q74-MAX(0,Z74)) | AE74: =MAX(0,R74-MAX(0,Z74-SUM(Q74:Q74))) | AF74: =MAX(0,S74-MAX(0,Z74-SUM(Q74:R74))) | AG74: =MAX(0,T74-MAX(0,Z74-SUM(Q74:S74))) | AH74: =MAX(0,U74-MAX(0,Z74-SUM(Q74:T74))) | AI74: =MAX(0,V74-MAX(0,Z74-SUM(Q74:U74))) | AJ74: =MAX(0,W74-MAX(0,Z74-SUM(Q74:V74))) | AK74: =MAX(0,X74-MAX(0,Z74-SUM(Q74:W74))) | AL74: =MAX(0,Y74-MAX(0,Z74-SUM(Q74:X74)))
...

Sheet Balance Summary
A1: BALANCE SUMMARY — remaining containers per BK No
A2: Balance = SUM(GP22..PC42) − Pickup qty. Only BK No with Balance > 0 are listed. Rows with no Pickup Name are highlighted amber and excluded from the grouped Summary.
A3: BK No | B3: VSL | C3: VOY | D3: Pickup | E3: Pickup Name | F3: TPSZ | G3: Booked Qty | H3: Pickup Qty | I3: Balance (Return) | J3: GP22 Remaining | K3: GP42 Remaining | L3: GP45 Remaining | M3: RE22 Remaining | N3: RE45 Remaining | O3: UT22 Remaining | P3: UT42 Remaining | Q3: PC22 Remaining | R3: PC42 Remaining
A4: =Data!A3 | B4: =Data!B3 | C4: =Data!C3 | D4: =Data!I3 | E4: =Data!J3 | F4: =Data!H3 | G4: =SUM(Data!Q3:Data!Y3) | H4: =Data!Z3 | I4: =Data!AB3 | J4: =Data!AD3 | K4: =Data!AE3 | L4: =Data!AF3 | M4: =Data!AG3 | N4: =Data!AH3 | O4: =Data!AI3 | P4: =Data!AJ3 | Q4: =Data!AK3 | R4: =Data!AL3
A5: =Data!A4 | B5: =Data!B4 | C5: =Data!C4 | D5: =Data!I4 | E5: =Data!J4 | F5: =Data!H4 | G5: =SUM(Data!Q4:Data!Y4) | H5: =Data!Z4 | I5: =Data!AB4 | J5: =Data!AD4 | K5: =Data!AE4 | L5: =Data!AF4 | M5: =Data!AG4 | N5: =Data!AH4 | O5: =Data!AI4 | P5: =Data!AJ4 | Q5: =Data!AK4 | R5: =Data!AL4
A6: =Data!A5 | B6: =Data!B5 | C6: =Data!C5 | D6: =Data!I5 | E6: =Data!J5 | F6: =Data!H5 | G6: =SUM(Data!Q5:Data!Y5) | H6: =Data!Z5 | I6: =Data!AB5 | J6: =Data!AD5 | K6: =Data!AE5 | L6: =Data!AF5 | M6: =Data!AG5 | N6: =Data!AH5 | O6: =Data!AI5 | P6: =Data!AJ5 | Q6: =Data!AK5 | R6: =Data!AL5
A7: =Data!A6 | B7: =Data!B6 | C7: =Data!C6 | D7: =Data!I6 | E7: =Data!J6 | F7: =Data!H6 | G7: =SUM(Data!Q6:Data!Y6) | H7: =Data!Z6 | I7: =Data!AB6 | J7: =Data!AD6 | K7: =Data!AE6 | L7: =Data!AF6 | M7: =Data!AG6 | N7: =Data!AH6 | O7: =Data!AI6 | P7: =Data!AJ6 | Q7: =Data!AK6 | R7: =Data!AL6
A8: =Data!A7 | B8: =Data!B7 | C8: =Data!C7 | D8: =Data!I7 | E8: =Data!J7 | F8: =Data!H7 | G8: =SUM(Data!Q7:Data!Y7) | H8: =Data!Z7 | I8: =Data!AB7 | J8: =Data!AD7 | K8: =Data!AE7 | L8: =Data!AF7 | M8: =Data!AG7 | N8: =Data!AH7 | O8: =Data!AI7 | P8: =Data!AJ7 | Q8: =Data!AK7 | R8: =Data!AL7
A9: =Data!A8 | B9: =Data!B8 | C9: =Data!C8 | D9: =Data!I8 | E9: =Data!J8 | F9: =Data!H8 | G9: =SUM(Data!Q8:Data!Y8) | H9: =Data!Z8 | I9: =Data!AB8 | J9: =Data!AD8 | K9: =Data!AE8 | L9: =Data!AF8 | M9: =Data!AG8 | N9: =Data!AH8 | O9: =Data!AI8 | P9: =Data!AJ8 | Q9: =Data!AK8 | R9: =Data!AL8
A10: =Data!A9 | B10: =Data!B9 | C10: =Data!C9 | D10: =Data!I9 | E10: =Data!J9 | F10: =Data!H9 | G10: =SUM(Data!Q9:Data!Y9) | H10: =Data!Z9 | I10: =Data!AB9 | J10: =Data!AD9 | K10: =Data!AE9 | L10: =Data!AF9 | M10: =Data!AG9 | N10: =Data!AH9 | O10: =Data!AI9 | P10: =Data!AJ9 | Q10: =Data!AK9 | R10: =Data!AL9
A11: =Data!A10 | B11: =Data!B10 | C11: =Data!C10 | D11: =Data!I10 | E11: =Data!J10 | F11: =Data!H10 | G11: =SUM(Data!Q10:Data!Y10) | H11: =Data!Z10 | I11: =Data!AB10 | J11: =Data!AD10 | K11: =Data!AE10 | L11: =Data!AF10 | M11: =Data!AG10 | N11: =Data!AH10 | O11: =Data!AI10 | P11: =Data!AJ10 | Q11: =Data!AK10 | R11: =Data!AL10
A12: =Data!A11 | B12: =Data!B11 | C12: =Data!C11 | D12: =Data!I11 | E12: =Data!J11 | F12: =Data!H11 | G12: =SUM(Data!Q11:Data!Y11) | H12: =Data!Z11 | I12: =Data!AB11 | J12: =Data!AD11 | K12: =Data!AE11 | L12: =Data!AF11 | M12: =Data!AG11 | N12: =Data!AH11 | O12: =Data!AI11 | P12: =Data!AJ11 | Q12: =Data!AK11 | R12: =Data!AL11
A13: =Data!A12 | B13: =Data!B12 | C13: =Data!C12 | D13: =Data!I12 | E13: =Data!J12 | F13: =Data!H12 | G13: =SUM(Data!Q12:Data!Y12) | H13: =Data!Z12 | I13: =Data!AB12 | J13: =Data!AD12 | K13: =Data!AE12 | L13: =Data!AF12 | M13: =Data!AG12 | N13: =Data!AH12 | O13: =Data!AI12 | P13: =Data!AJ12 | Q13: =Data!AK12 | R13: =Data!AL12
A14: =Data!A13 | B14: =Data!B13 | C14: =Data!C13 | D14: =Data!I13 | E14: =Data!J13 | F14: =Data!H13 | G14: =SUM(Data!Q13:Data!Y13) | H14: =Data!Z13 | I14: =Data!AB13 | J14: =Data!AD13 | K14: =Data!AE13 | L14: =Data!AF13 | M14: =Data!AG13 | N14: =Data!AH13 | O14: =Data!AI13 | P14: =Data!AJ13 | Q14: =Data!AK13 | R14: =Data!AL13
A15: =Data!A14 | B15: =Data!B14 | C15: =Data!C14 | D15: =Data!I14 | E15: =Data!J14 | F15: =Data!H14 | G15: =SUM(Data!Q14:Data!Y14) | H15: =Data!Z14 | I15: =Data!AB14 | J15: =Data!AD14 | K15: =Data!AE14 | L15: =Data!AF14 | M15: =Data!AG14 | N15: =Data!AH14 | O15: =Data!AI14 | P15: =Data!AJ14 | Q15: =Data!AK14 | R15: =Data!AL14
... A81: =Data!A80 | B81: =Data!B80 | C81: =Data!C80 | D81: =Data!I80 | E81: =Data!J80 | F81: =Data!H80 | G81: =SUM(Data!Q80:Data!Y80) | H81: =Data!Z80 | I81: =Data!AB80 | J81: =Data!AD80 | K81: =Data!AE80 | L81: =Data!AF80 | M81: =Data!AG80 | N81: =Data!AH80 | O81: =Data!AI80 | P81: =Data!AJ80 | Q81: =Data!AK80 | R81: =Data!AL80
A82: TOTAL | G82: =SUM(G4:G81) | H82: =SUM(H4:H81) | I82: =SUM(I4:I81) | J82: =SUM(J4:J81) | K82: =SUM(K4:K81) | L82: =SUM(L4:L81) | M82: =SUM(M4:M81) | N82: =SUM(N4:N81) | ... R82: =SUM(R4:R81)

Sheet Summary
A1: SUMMARY — outstanding containers grouped by Pickup depot
A2: Group | B2: Pickup | C2: Pickup Name | D2: Number of Records | E2: GP22 | F2: GP42 | G2: GP45 | H2: RE22 | I2: RE45 | J2: UT22 | K2: UT42 | L2: PC22 | M2: PC42 | N2: Total Containers
A3: BKK | B3: BKK01+BKK04 | C3: PAT TERMINAL 1 & 2 (PORT AUTHORITY OF THAILAND) | D3: =COUNTIF(Data!$I:$I,"BKK01")+COUNTIF(Data!$I:$I,"BKK04") | E3: =SUMIF(Data!$I:$I,"BKK01",Data!$AD:$AD)+SUMIF(Data!$I:$I,"BKK04",Data!$AD:$AD) | F3: =SUMIF(Data!$I:$I,"BKK01",Data!$AE:$AE)+SUMIF(Data!$I:$I,"BKK04",Data!$AE:$AE) | G3: =SUMIF(Data!$I:$I,"BKK01",Data!$AF:$AF)+SUMIF(Data!$I:$I,"BKK04",Data!$AF:$AF) | H3: =SUMIF(Data!$I:$I,"BKK01",Data!$AG:$AG)+SUMIF(Data!$I:$I,"BKK04",Data!$AG:$AG) | I3: =SUMIF(Data!$I:$I,"BKK01",Data!$AH:$AH)+SUMIF(Data!$I:$I,"BKK04",Data!$AH:$AH) | J3: =SUMIF(Data!$I:$I,"BKK01",Data!$AI:$AI)+SUMIF(Data!$I:$I,"BKK04",Data!$AI:$AI) | K3: =SUMIF(Data!$I:$I,"BKK01",Data!$AJ:$AJ)+SUMIF(Data!$I:$I,"BKK04",Data!$AJ:$AJ) | L3: =SUMIF(Data!$I:$I,"BKK01",Data!$AK:$AK)+SUMIF(Data!$I:$I,"BKK04",Data!$AK:$AK) | M3: =SUMIF(Data!$I:$I,"BKK01",Data!$AL:$AL)+SUMIF(Data!$I:$I,"BKK04",Data!$AL:$AL) | N3: =SUM(E3:M3)
A4: BKK | B4: BKK25 | C4: Smart Logistics Service (Thailand ) Co.,Ltd. | D4: =COUNTIF(Data!$I:$I,"BKK25") | E4: =SUMIF(Data!$I:$I,"BKK25",Data!$AD:$AD) | F4: =SUMIF(Data!$I:$I,"BKK25",Data!$AE:$AE) | G4: =SUMIF(Data!$I:$I,"BKK25",Data!$AF:$AF) | H4: =SUMIF(Data!$I:$I,"BKK25",Data!$AG:$AG) | I4: =SUMIF(Data!$I:$I,"BKK25",Data!$AH:$AH) | J4: =SUMIF(Data!$I:$I,"BKK25",Data!$AI:$AI) | K4: =SUMIF(Data!$I:$I,"BKK25",Data!$AJ:$AJ) | L4: =SUMIF(Data!$I:$I,"BKK25",Data!$AK:$AK) | M4: =SUMIF(Data!$I:$I,"BKK25",Data!$AL:$AL) | N4: =SUM(E4:M4)
A5: BKK | B5: BKK27 | C5: B.C. DEPOT CO.,LTD. ( Bang-Na KM.18) | D5: =COUNTIF(Data!$I:$I,"BKK27") | E5: =SUMIF(Data!$I:$I,"BKK27",Data!$AD:$AD) | F5: =SUMIF(Data!$I:$I,"BKK27",Data!$AE:$AE) | G5: =SUMIF(Data!$I:$I,"BKK27",Data!$AF:$AF) | H5: =SUMIF(Data!$I:$I,"BKK27",Data!$AG:$AG) | I5: =SUMIF(Data!$I:$I,"BKK27",Data!$AH:$AH) | J5: =SUMIF(Data!$I:$I,"BKK27",Data!$AI:$AI) | K5: =SUMIF(Data!$I:$I,"BKK27",Data!$AJ:$AJ) | L5: =SUMIF(Data!$I:$I,"BKK27",Data!$AK:$AK) | M5: =SUMIF(Data!$I:$I,"BKK27",Data!$AL:$AL) | N5: =SUM(E5:M5)
A6: LCH | B6: LCH27 | C6: HAST Logistics Co.,Ltd. | D6: =COUNTIF(Data!$I:$I,"LCH27") | E6: =SUMIF(Data!$I:$I,"LCH27",Data!$AD:$AD) | F6: =SUMIF(Data!$I:$I,"LCH27",Data!$AE:$AE) | G6: =SUMIF(Data!$I:$I,"LCH27",Data!$AF:$AF) | H6: =SUMIF(Data!$I:$I,"LCH27",Data!$AG:$AG) | I6: =SUMIF(Data!$I:$I,"LCH27",Data!$AH:$AH) | J6: =SUMIF(Data!$I:$I,"LCH27",Data!$AI:$AI) | K6: =SUMIF(Data!$I:$I,"LCH27",Data!$AJ:$AJ) | L6: =SUMIF(Data!$I:$I,"LCH27",Data!$AK:$AK) | M6: =SUMIF(Data!$I:$I,"LCH27",Data!$AL:$AL) | N6: =SUM(E6:M6)
A7: LCH | B7: LCH28 | C7: CELLO | D7: =COUNTIF(Data!$I:$I,"LCH28") | E7: =SUMIF(Data!$I:$I,"LCH28",Data!$AD:$AD) | F7: =SUMIF(Data!$I:$I,"LCH28",Data!$AE:$AE) | G7: =SUMIF(Data!$I:$I,"LCH28",Data!$AF:$AF) | H7: =SUMIF(Data!$I:$I,"LCH28",Data!$AG:$AG) | I7: =SUMIF(Data!$I:$I,"LCH28",Data!$AH:$AH) | J7: =SUMIF(Data!$I:$I,"LCH28",Data!$AI:$AI) | K7: =SUMIF(Data!$I:$I,"LCH28",Data!$AJ:$AJ) | L7: =SUMIF(Data!$I:$I,"LCH28",Data!$AK:$AK) | M7: =SUMIF(Data!$I:$I,"LCH28",Data!$AL:$AL) | N7: =SUM(E7:M7)
A8: LCH | B8: LCH54 | C8: TIFFA LOGISTICS CENTER CO., LTD. | D8: =COUNTIF(Data!$I:$I,"LCH54") | E8: =SUMIF(Data!$I:$I,"LCH54",Data!$AD:$AD) | F8: =SUMIF(Data!$I:$I,"LCH54",Data!$AE:$AE) | G8: =SUMIF(Data!$I:$I,"LCH54",Data!$AF:$AF) | H8: =SUMIF(Data!$I:$I,"LCH54",Data!$AG:$AG) | I8: =SUMIF(Data!$I:$I,"LCH54",Data!$AH:$AH) | J8: =SUMIF(Data!$I:$I,"LCH54",Data!$AI:$AI) | K8: =SUMIF(Data!$I:$I,"LCH54",Data!$AJ:$AJ) | L8: =SUMIF(Data!$I:$I,"LCH54",Data!$AK:$AK) | M8: =SUMIF(Data!$I:$I,"LCH54",Data!$AL:$AL) | N8: =SUM(E8:M8)
A9: LCH | B9: LCHY5 | C9: PW DEPOT CO., LTD. | D9: =COUNTIF(Data!$I:$I,"LCHY5") | E9: =SUMIF(Data!$I:$I,"LCHY5",Data!$AD:$AD) | F9: =SUMIF(Data!$I:$I,"LCHY5",Data!$AE:$AE) | G9: =SUMIF(Data!$I:$I,"LCHY5",Data!$AF:$AF) | H9: =SUMIF(Data!$I:$I,"LCHY5",Data!$AG:$AG) | I9: =SUMIF(Data!$I:$I,"LCHY5",Data!$AH:$AH) | J9: =SUMIF(Data!$I:$I,"LCHY5",Data!$AI:$AI) | K9: =SUMIF(Data!$I:$I,"LCHY5",Data!$AJ:$AJ) | L9: =SUMIF(Data!$I:$I,"LCHY5",Data!$AK:$AK) | M9: =SUMIF(Data!$I:$I,"LCHY5",Data!$AL:$AL) | N9: =SUM(E9:M9)
A10: TOTAL | D10: =SUM(D3:D9) | E10: =SUM(E3:E9) | F10: =SUM(F3:F9) | G10: =SUM(G3:G9) | H10: =SUM(H3:H9) | I10: =SUM(I3:I9) | J10: =SUM(J3:J9) | K10: =SUM(K3:K9) | ... N10: =SUM(N3:N9)
C13: Group | D13: Number of Records | E13: GP22 | F13: GP42 | G13: GP45 | H13: RE22 | I13: RE45 | J13: UT22 | K13: UT42 | L13: PC22 | M13: PC42 | N13: Total Containers
C14: BKK | D14: =COUNTIF(Data!$AC:$AC,"BKK") | E14: =SUMIF(Data!$AC:$AC,"BKK",Data!$AD:$AD) | F14: =SUMIF(Data!$AC:$AC,"BKK",Data!$AE:$AE) | G14: =SUMIF(Data!$AC:$AC,"BKK",Data!$AF:$AF) | H14: =SUMIF(Data!$AC:$AC,"BKK",Data!$AG:$AG) | I14: =SUMIF(Data!$AC:$AC,"BKK",Data!$AH:$AH) | J14: =SUMIF(Data!$AC:$AC,"BKK",Data!$AI:$AI) | K14: =SUMIF(Data!$AC:$AC,"BKK",Data!$AJ:$AJ) | L14: =SUMIF(Data!$AC:$AC,"BKK",Data!$AK:$AK) | M14: =SUMIF(Data!$AC:$AC,"BKK",Data!$AL:$AL) | N14: =SUM(E14:M14)
C15: LCH | D15: =COUNTIF(Data!$AC:$AC,"LCH") | E15: =SUMIF(Data!$AC:$AC,"LCH",Data!$AD:$AD) | F15: =SUMIF(Data!$AC:$AC,"LCH",Data!$AE:$AE) | G15: =SUMIF(Data!$AC:$AC,"LCH",Data!$AF:$AF) | H15: =SUMIF(Data!$AC:$AC,"LCH",Data!$AG:$AG) | I15: =SUMIF(Data!$AC:$AC,"LCH",Data!$AH:$AH) | J15: =SUMIF(Data!$AC:$AC,"LCH",Data!$AI:$AI) | K15: =SUMIF(Data!$AC:$AC,"LCH",Data!$AJ:$AJ) | L15: =SUMIF(Data!$AC:$AC,"LCH",Data!$AK:$AK) | M15: =SUMIF(Data!$AC:$AC,"LCH",Data!$AL:$AL) | N15: =SUM(E15:M15)
C16: GRAND TOTAL | D16: =SUM(D14:D15) | E16: =SUM(E14:E15) | F16: =SUM(F14:F15) | G16: =SUM(G14:G15) | H16: =SUM(H14:H15) | I16: =SUM(I14:I15) | J16: =SUM(J14:J15) | K16: =SUM(K14:K15) | ... N16: =SUM(N14:N15)
